Workbook

Sheet Dashboard
B2: RFI LOG DASHBOARD DP06
B5: TOTAL ITEMS | D5: PENDING | F5: RESPONDED
B7: =COUNTIF(RFI!$D$5:$D$5012,"?*") -> 96 | D7: =COUNTIFS(RFI!$D$5:$D$5012,"?*",RFI!$O$5:$O$5012,"open*") -> 35 | F7: =COUNTIFS(RFI!$D$5:$D$5012,"?*",RFI!$O$5:$O$5012,"Response*") -> 61
B11: Discipline | C11: Total | D11: Pending | E11: Responded | F11: Response Rate
B12: Architectural | C12: =COUNTIF(RFI!$Q$5:$Q$4998,B12) -> 10 | D12: =COUNTIFS(RFI!$Q$5:$Q$4998,B12,RFI!$O$5:$O$5012,"open*") -> #VALUE! | E12: =COUNTIFS(RFI!$Q$5:$Q$4998,B12,RFI!$O$5:$O$5012,"Response*") -> #VALUE! | F12: =IFERROR(E12/C12,0) -> 0
B13: Structural | C13: =COUNTIF(RFI!$Q$5:$Q$4998,B13) -> 61 | D13: =COUNTIFS(RFI!$Q$5:$Q$4998,B13,RFI!$O$5:$O$5012,"open*") -> #VALUE! | E13: =COUNTIFS(RFI!$Q$5:$Q$4998,B13,RFI!$O$5:$O$5012,"Response*") -> #VALUE! | F13: =IFERROR(E13/C13,0) -> 0
B14: Mechanical | C14: =COUNTIF(RFI!$Q$5:$Q$4998,B14) -> 4 | D14: =COUNTIFS(RFI!$Q$5:$Q$4998,B14,RFI!$O$5:$O$5012,"open*") -> #VALUE! | E14: =COUNTIFS(RFI!$Q$5:$Q$4998,B14,RFI!$O$5:$O$5012,"Response*") -> #VALUE! | F14: =IFERROR(E14/C14,0) -> 0
B15: Electrical | C15: =COUNTIF(RFI!$Q$5:$Q$4998,B15) -> 5 | D15: =COUNTIFS(RFI!$Q$5:$Q$4998,B15,RFI!$O$5:$O$5012,"open*") -> #VALUE! | E15: =COUNTIFS(RFI!$Q$5:$Q$4998,B15,RFI!$O$5:$O$5012,"Response*") -> #VALUE! | F15: =IFERROR(E15/C15,0) -> 0
B16: General | C16: =COUNTIF(RFI!$Q$5:$Q$4998,B16) -> 1 | D16: =COUNTIFS(RFI!$Q$5:$Q$4998,B16,RFI!$O$5:$O$5012,"open*") -> #VALUE! | E16: =COUNTIFS(RFI!$Q$5:$Q$4998,B16,RFI!$O$5:$O$5012,"Response*") -> #VALUE! | F16: =IFERROR(E16/C16,0) -> 0
B17: GRAND TOTAL | C17: =SUM(C12:C16) -> 81 | D17: =SUM(D12:D16) -> #VALUE! | E17: =SUM(E12:E16) -> #VALUE! | F17: =IFERROR(E17/C17,0) -> 0
B19: Month | C19: Total | D19: Pending | E19: Responded
B20: 46174 | C20: =COUNTIFS(RFI!$R$5:$R$4998,">="&B20,RFI!$R$5:$R$4998,"<"&EDATE(B20,1)) -> 6 | D20: =COUNTIFS(RFI!$R$5:$R$4998,">="&B20,RFI!$R$5:$R$4998,"<"&EDATE(B20,1),RFI!$O$5:$O$5012,"open*") -> #VALUE! | E20: =COUNTIFS(RFI!$R$5:$R$4998,">="&B20,RFI!$R$5:$R$4998,"<"&EDATE(B20,1),RFI!$O$5:$O$5012,"Response*") -> #VALUE!
B21: 46204 | C21: =COUNTIFS(RFI!$R$5:$R$4998,">="&B21,RFI!$R$5:$R$4998,"<"&EDATE(B21,1)) -> 9 | D21: =COUNTIFS(RFI!$R$5:$R$4998,">="&B21,RFI!$R$5:$R$4998,"<"&EDATE(B21,1),RFI!$O$5:$O$5012,"open*") -> #VALUE! | E21: =COUNTIFS(RFI!$R$5:$R$4998,">="&B21,RFI!$R$5:$R$4998,"<"&EDATE(B21,1),RFI!$O$5:$O$5012,"Response*") -> #VALUE!
B22: 46235 | C22: =COUNTIFS(RFI!$R$5:$R$4998,">="&B22,RFI!$R$5:$R$4998,"<"&EDATE(B22,1)) -> 21 | D22: =COUNTIFS(RFI!$R$5:$R$4998,">="&B22,RFI!$R$5:$R$4998,"<"&EDATE(B22,1),RFI!$O$5:$O$5012,"open*") -> #VALUE! | E22: =COUNTIFS(RFI!$R$5:$R$4998,">="&B22,RFI!$R$5:$R$4998,"<"&EDATE(B22,1),RFI!$O$5:$O$5012,"Response*") -> #VALUE!
B23: 46266 | C23: =COUNTIFS(RFI!$R$5:$R$4998,">="&B23,RFI!$R$5:$R$4998,"<"&EDATE(B23,1)) -> 41 | D23: =COUNTIFS(RFI!$R$5:$R$4998,">="&B23,RFI!$R$5:$R$4998,"<"&EDATE(B23,1),RFI!$O$5:$O$5012,"open*") -> #VALUE! | E23: =COUNTIFS(RFI!$R$5:$R$4998,">="&B23,RFI!$R$5:$R$4998,"<"&EDATE(B23,1),RFI!$O$5:$O$5012,"Response*") -> #VALUE!
B24: 46296 | C24: =COUNTIFS(RFI!$R$5:$R$4998,">="&B24,RFI!$R$5:$R$4998,"<"&EDATE(B24,1)) -> 4 | D24: =COUNTIFS(RFI!$R$5:$R$4998,">="&B24,RFI!$R$5:$R$4998,"<"&EDATE(B24,1),RFI!$O$5:$O$5012,"open*") -> #VALUE! | E24: =COUNTIFS(RFI!$R$5:$R$4998,">="&B24,RFI!$R$5:$R$4998,"<"&EDATE(B24,1),RFI!$O$5:$O$5012,"Response*") -> #VALUE!
B26: Discipline | D26: Pending | E26: Responded
B27: Architectural | D27: =COUNTIFS(RFI!$Q$5:$Q$4998,B27,RFI!$O$5:$O$5012,"open*") -> #VALUE! | E27: =COUNTIFS(RFI!$Q$5:$Q$4998,B27,RFI!$O$5:$O$5012,"Response*") -> #VALUE!
B28: Structural | D28: =COUNTIFS(RFI!$Q$5:$Q$4998,B28,RFI!$O$5:$O$5012,"open*") -> #VALUE! | E28: =COUNTIFS(RFI!$Q$5:$Q$4998,B28,RFI!$O$5:$O$5012,"Response*") -> #VALUE!
B29: Mechanical | D29: =COUNTIFS(RFI!$Q$5:$Q$4998,B29,RFI!$O$5:$O$5012,"open*") -> #VALUE! | E29: =COUNTIFS(RFI!$Q$5:$Q$4998,B29,RFI!$O$5:$O$5012,"Response*") -> #VALUE!
B30: Electrical | D30: =COUNTIFS(RFI!$Q$5:$Q$4998,B30,RFI!$O$5:$O$5012,"open*") -> #VALUE! | E30: =COUNTIFS(RFI!$Q$5:$Q$4998,B30,RFI!$O$5:$O$5012,"Response*") -> #VALUE!
B31: General | D31: =COUNTIFS(RFI!$Q$5:$Q$4998,B31,RFI!$O$5:$O$5012,"open*") -> #VALUE! | E31: =COUNTIFS(RFI!$Q$5:$Q$4998,B31,RFI!$O$5:$O$5012,"Response*") -> #VALUE!

Sheet RFI
A1: (RFI) - Request For Information Log For Design Pakage DP06 | O1: ALL | P1: =COUNTIF(D$5:D$5012,"?*") -> 96
O2: Response | P2: =COUNTIFS(D$5:D$5012,"?*",O$5:O$5012,"Response*") -> 61
A3: HAC TO HILL | G3: Hill to shaker | I3: Hill to AEDAS | K3: Dewan to hill | M3: hill TO HAC | O3: open | P3: =COUNTIFS(D$5:D$5012,"?*",O$5:O$5012,"open*") -> 35
A4: Mail No | B4: Mail No | C4: REV | D4: RFI No | E4: Subject | F4: Date | G4: Mail No2 | H4: Date3 | I4: Mail No4 | J4: Date5 | K4: Mail No6 | L4: Date7 | M4: Mail No8 | N4: Date9 | O4: Status | P4: Notes | Q4: Discipline (Auto) | R4: RFI Date (Auto)
B5: HAC-RFI-000057 | C5: 0 | D5: P1000-K03206-HA-HI-ST-RFI-000001 | E5: for Missing Details Related to Hotel Excavation and Blinding Works (DP6-Hotel). | F5: 46193 | G5: HillInt-RFI-000587 | H5: 24/06/2026 | M5: HillInt-RTRFI-000754 | N5: 46212 | O5: Response | Q5: =IF(COUNTA(A5:P5)=0,"",IF(ISNUMBER(SEARCH("-AR-",E5)),"Architectural",IF(ISNUMBER(SEARCH("-ST-",E5)),"Structural",IF(ISNUMBER(SEARCH("-ME-",E5)),"Mechanical",IF(ISNUMBER(SEARCH("-EL-",E5)),"Electrical",IF(ISNUMBER(SEARCH("-GE-",E5)),"General",IF(ISNUMBER(SEARCH("-AR-",D5)),"Architectural",IF(ISNUMBER(SEARCH("-ST-",D5)),"Structural",IF(ISNUMBER(SEARCH("-ME-",D5)),"Mechanical",IF(ISNUMBER(SEARCH("-EL-",D5)),"Electrical",IF(ISNUMBER(SEARCH("-GE-",D5)),"General","Other"))))))))))) -> Structural | R5: =IF(F5="","",IFERROR(IF(ISNUMBER(F5),F5,DATEVALUE(F5)),"")) -> 46193
B6: HAC-RFI-000058 | C6: 0 | D6: P1000-K03206-HA-HI-ST-RFI-000002 | E6: for Proposed Project Sign Board Location for Approval (At the entrance of DP06 project). | F6: 46193 | G6: HillInt-RFI-000588 | H6: 24/06/2026 | M6: HillInt-RTRFI-000750 3 39 1 | N6: 46212 | O6: Response | Q6: =IF(COUNTA(A6:P6)=0,"",IF(ISNUMBER(SEARCH("-AR-",E6)),"Architectural",IF(ISNUMBER(SEARCH("-ST-",E6)),"Structural",IF(ISNUMBER(SEARCH("-ME-",E6)),"Mechanical",IF(ISNUMBER(SEARCH("-EL-",E6)),"Electrical",IF(ISNUMBER(SEARCH("-GE-",E6)),"General",IF(ISNUMBER(SEARCH("-AR-",D6)),"Architectural",IF(ISNUMBER(SEARCH("-ST-",D6)),"Structural",IF(ISNUMBER(SEARCH("-ME-",D6)),"Mechanical",IF(ISNUMBER(SEARCH("-EL-",D6)),"Electrical",IF(ISNUMBER(SEARCH("-GE-",D6)),"General","Other"))))))))))) -> Structural | R6: =IF(F6="","",IFERROR(IF(ISNUMBER(F6),F6,DATEVALUE(F6)),"")) -> 46193
B7: HAC-RFI-000146 | C7: 1 | D7: P1000-K03206-HA-HI-ST-RFI-000002 | E7: for Proposed Project Sign Board Location for Approval (At the entrance of DP06 project). | F7: 46303 | G7: HillInt-RFI-000910 | H7: 46246 | I7: HillInt-RFI-000910 | J7: 46246 | M7: HillInt-GNC-004142 | O7: Response | Q7: =IF(COUNTA(A7:P7)=0,"",IF(ISNUMBER(SEARCH("-AR-",E7)),"Architectural",IF(ISNUMBER(SEARCH("-ST-",E7)),"Structural",IF(ISNUMBER(SEARCH("-ME-",E7)),"Mechanical",IF(ISNUMBER(SEARCH("-EL-",E7)),"Electrical",IF(ISNUMBER(SEARCH("-GE-",E7)),"General",IF(ISNUMBER(SEARCH("-AR-",D7)),"Architectural",IF(ISNUMBER(SEARCH("-ST-",D7)),"Structural",IF(ISNUMBER(SEARCH("-ME-",D7)),"Mechanical",IF(ISNUMBER(SEARCH("-EL-",D7)),"Electrical",IF(ISNUMBER(SEARCH("-GE-",D7)),"General","Other"))))))))))) -> Structural | R7: =IF(F7="","",IFERROR(IF(ISNUMBER(F7),F7,DATEVALUE(F7)),"")) -> 46303
A8: CCCEGY-RFI-000001 | B8: HAC-RFI-000059 | C8: 0 | D8: P1000-K03206-HA-HI-ST-RFI-000003 | E8: for DP06 Dump area, Main Mobilizations and Site Mobilization Location. | F8: 46193 | G8: HillInt-RFI-000589 | H8: 24/06/2026 | M8: HillInt-RTRFI-000751 | N8: 46212 | O8: Response | Q8: =IF(COUNTA(A8:P8)=0,"",IF(ISNUMBER(SEARCH("-AR-",E8)),"Architectural",IF(ISNUMBER(SEARCH("-ST-",E8)),"Structural",IF(ISNUMBER(SEARCH("-ME-",E8)),"Mechanical",IF(ISNUMBER(SEARCH("-EL-",E8)),"Electrical",IF(ISNUMBER(SEARCH("-GE-",E8)),"General",IF(ISNUMBER(SEARCH("-AR-",D8)),"Architectural",IF(ISNUMBER(SEARCH("-ST-",D8)),"Structural",IF(ISNUMBER(SEARCH("-ME-",D8)),"Mechanical",IF(ISNUMBER(SEARCH("-EL-",D8)),"Electrical",IF(ISNUMBER(SEARCH("-GE-",D8)),"General","Other"))))))))))) -> Structural | R8: =IF(F8="","",IFERROR(IF(ISNUMBER(F8),F8,DATEVALUE(F8)),"")) -> 46193
A9: CCCEGY-RFI-000002 | B9: HAC-RFI-000060 | C9: 0 | D9: P1000-K03206-HA-HI-ST-RFI-000004 | E9: for DP06 Access Roads approval (At the entrance of DP06 project). | F9: 46193 | G9: HillInt-RFI-000590 | H9: 24/06/2026 | O9: open | Q9: =IF(COUNTA(A9:P9)=0,"",IF(ISNUMBER(SEARCH("-AR-",E9)),"Architectural",IF(ISNUMBER(SEARCH("-ST-",E9)),"Structural",IF(ISNUMBER(SEARCH("-ME-",E9)),"Mechanical",IF(ISNUMBER(SEARCH("-EL-",E9)),"Electrical",IF(ISNUMBER(SEARCH("-GE-",E9)),"General",IF(ISNUMBER(SEARCH("-AR-",D9)),"Architectural",IF(ISNUMBER(SEARCH("-ST-",D9)),"Structural",IF(ISNUMBER(SEARCH("-ME-",D9)),"Mechanical",IF(ISNUMBER(SEARCH("-EL-",D9)),"Electrical",IF(ISNUMBER(SEARCH("-GE-",D9)),"General","Other"))))))))))) -> Structural | R9: =IF(F9="","",IFERROR(IF(ISNUMBER(F9),F9,DATEVALUE(F9)),"")) -> 46193
A10: CCCEGY-RFI-000003 | B10: HAC-RFI-000061 | C10: 0 | D10: P1000-K03206-HA-HI-ST-RFI-000005 | E10: for Request for Temporary 12 m Boundary Offset for Construction Access (DP6). | F10: 46193 | G10: HillInt-RFI-000591 | H10: 24/06/2026 | M10: SHKECGCR-RTRFI-000010 | N10: 46204 | O10: Response | Q10: =IF(COUNTA(A10:P10)=0,"",IF(ISNUMBER(SEARCH("-AR-",E10)),"Architectural",IF(ISNUMBER(SEARCH("-ST-",E10)),"Structural",IF(ISNUMBER(SEARCH("-ME-",E10)),"Mechanical",IF(ISNUMBER(SEARCH("-EL-",E10)),"Electrical",IF(ISNUMBER(SEARCH("-GE-",E10)),"General",IF(ISNUMBER(SEARCH("-AR-",D10)),"Architectural",IF(ISNUMBER(SEARCH("-ST-",D10)),"Structural",IF(ISNUMBER(SEARCH("-ME-",D10)),"Mechanical",IF(ISNUMBER(SEARCH("-EL-",D10)),"Electrical",IF(ISNUMBER(SEARCH("-GE-",D10)),"General","Other"))))))))))) -> Structural | R10: =IF(F10="","",IFERROR(IF(ISNUMBER(F10),F10,DATEVALUE(F10)),"")) -> 46193
B11: HAC-RFI-000069 | C11: 0 | D11: P1000-K03206-HA-HI-ST-RFI-000006 | E11: for Existing Military Building Obstructing Villa C1-25 and Access Road (DP6-Villa C1-25). | F11: 46193 | G11: HAC-RFI-000069 | H11: 25/06/2026 | M11: HillInt-RTRFI-000753 | N11: 46212 | O11: Response | Q11: =IF(COUNTA(A11:P11)=0,"",IF(ISNUMBER(SEARCH("-AR-",E11)),"Architectural",IF(ISNUMBER(SEARCH("-ST-",E11)),"Structural",IF(ISNUMBER(SEARCH("-ME-",E11)),"Mechanical",IF(ISNUMBER(SEARCH("-EL-",E11)),"Electrical",IF(ISNUMBER(SEARCH("-GE-",E11)),"General",IF(ISNUMBER(SEARCH("-AR-",D11)),"Architectural",IF(ISNUMBER(SEARCH("-ST-",D11)),"Structural",IF(ISNUMBER(SEARCH("-ME-",D11)),"Mechanical",IF(ISNUMBER(SEARCH("-EL-",D11)),"Electrical",IF(ISNUMBER(SEARCH("-GE-",D11)),"General","Other"))))))))))) -> Structural | R11: =IF(F11="","",IFERROR(IF(ISNUMBER(F11),F11,DATEVALUE(F11)),"")) -> 46193
B12: HAC-RFI-000080 | C12: 0 | D12: P1000-K03206-HA-HI-AR-RFI-000007 | E12: for Request for Approval of Proposed Hotel Mock-Up Strategy ( At Hotel of DP06 project). | F12: 46206 | I12: HillInt-RFI-000622 | J12: 46207 | O12: open | Q12: =IF(COUNTA(A12:P12)=0,"",IF(ISNUMBER(SEARCH("-AR-",E12)),"Architectural",IF(ISNUMBER(SEARCH("-ST-",E12)),"Structural",IF(ISNUMBER(SEARCH("-ME-",E12)),"Mechanical",IF(ISNUMBER(SEARCH("-EL-",E12)),"Electrical",IF(ISNUMBER(SEARCH("-GE-",E12)),"General",IF(ISNUMBER(SEARCH("-AR-",D12)),"Architectural",IF(ISNUMBER(SEARCH("-ST-",D12)),"Structural",IF(ISNUMBER(SEARCH("-ME-",D12)),"Mechanical",IF(ISNUMBER(SEARCH("-EL-",D12)),"Electrical",IF(ISNUMBER(SEARCH("-GE-",D12)),"General","Other"))))))))))) -> Architectural | R12: =IF(F12="","",IFERROR(IF(ISNUMBER(F12),F12,DATEVALUE(F12)),"")) -> 46206
B13: HAC-RFI-000081 | C13: 0 | D13: P1000-K03206-HA-HI-AR-RFI-000008 | E13: Request for Approval of Proposed Villas Mock-Up Strategy (Villa mockups). | F13: 46206 | I13: HillInt-RFI-000621 | J13: 46207 | M13: HillInt-RTRFI-001118 | N13: 46261 | O13: Response | Q13: =IF(COUNTA(A13:P13)=0,"",IF(ISNUMBER(SEARCH("-AR-",E13)),"Architectural",IF(ISNUMBER(SEARCH("-ST-",E13)),"Structural",IF(ISNUMBER(SEARCH("-ME-",E13)),"Mechanical",IF(ISNUMBER(SEARCH("-EL-",E13)),"Electrical",IF(ISNUMBER(SEARCH("-GE-",E13)),"General",IF(ISNUMBER(SEARCH("-AR-",D13)),"Architectural",IF(ISNUMBER(SEARCH("-ST-",D13)),"Structural",IF(ISNUMBER(SEARCH("-ME-",D13)),"Mechanical",IF(ISNUMBER(SEARCH("-EL-",D13)),"Electrical",IF(ISNUMBER(SEARCH("-GE-",D13)),"General","Other"))))))))))) -> Architectural | R13: =IF(F13="","",IFERROR(IF(ISNUMBER(F13),F13,DATEVALUE(F13)),"")) -> 46206
B14: HAC-RFI-000097 | C14: 0 | D14: P1000-K03206-HA-HI-GE-RFI-000009 | E14: P1000-K03206-HA-HI-GE-RFI-000009 for DP6 Drawing Naming Convention. | F14: 46216 | I14: HillInt-RFI-001084 | J14: 46261 | O14: open | Q14: =IF(COUNTA(A14:P14)=0,"",IF(ISNUMBER(SEARCH("-AR-",E14)),"Architectural",IF(ISNUMBER(SEARCH("-ST-",E14)),"Structural",IF(ISNUMBER(SEARCH("-ME-",E14)),"Mechanical",IF(ISNUMBER(SEARCH("-EL-",E14)),"Electrical",IF(ISNUMBER(SEARCH("-GE-",E14)),"General",IF(ISNUMBER(SEARCH("-AR-",D14)),"Architectural",IF(ISNUMBER(SEARCH("-ST-",D14)),"Structural",IF(ISNUMBER(SEARCH("-ME-",D14)),"Mechanical",IF(ISNUMBER(SEARCH("-EL-",D14)),"Electrical",IF(ISNUMBER(SEARCH("-GE-",D14)),"General","Other"))))))))))) -> General | R14: =IF(F14="","",IFERROR(IF(ISNUMBER(F14),F14,DATEVALUE(F14)),"")) -> 46216
B15: HAC-RFI-000117 | C15: 0 | D15: P1000-K03206-HA-HI-GE-RFI-000010 | E15: P1000-K03206-HA-HI-EL-RFI-000010 for Mockup's Lighting Shopdrawing Requirement (3BR VIP suit mockup). | F15: 46233 | I15: HillInt-RFI-000895 | J15: 46248 | O15: open | Q15: =IF(COUNTA(A15:P15)=0,"",IF(ISNUMBER(SEARCH("-AR-",E15)),"Architectural",IF(ISNUMBER(SEARCH("-ST-",E15)),"Structural",IF(ISNUMBER(SEARCH("-ME-",E15)),"Mechanical",IF(ISNUMBER(SEARCH("-EL-",E15)),"Electrical",IF(ISNUMBER(SEARCH("-GE-",E15)),"General",IF(ISNUMBER(SEARCH("-AR-",D15)),"Architectural",IF(ISNUMBER(SEARCH("-ST-",D15)),"Structural",IF(ISNUMBER(SEARCH("-ME-",D15)),"Mechanical",IF(ISNUMBER(SEARCH("-EL-",D15)),"Electrical",IF(ISNUMBER(SEARCH("-GE-",D15)),"General","Other"))))))))))) -> Electrical | R15: =IF(F15="","",IFERROR(IF(ISNUMBER(F15),F15,DATEVALUE(F15)),"")) -> 46233
B16: HAC-RFI-000118 | C16: 0 | D16: P1000-K03206-HA-HI-GE-RFI-000011 | E16: P1000-K03206-HA-HI-EL-RFI-000011 for Mockup's Emergency Lighting Shopdrawing Requirement (3BR VIP suit mockup). | F16: 46233 | I16: HillInt-RFI-000896 | J16: 46248 | O16: open | Q16: =IF(COUNTA(A16:P16)=0,"",IF(ISNUMBER(SEARCH("-AR-",E16)),"Architectural",IF(ISNUMBER(SEARCH("-ST-",E16)),"Structural",IF(ISNUMBER(SEARCH("-ME-",E16)),"Mechanical",IF(ISNUMBER(SEARCH("-EL-",E16)),"Electrical",IF(ISNUMBER(SEARCH("-GE-",E16)),"General",IF(ISNUMBER(SEARCH("-AR-",D16)),"Architectural",IF(ISNUMBER(SEARCH("-ST-",D16)),"Structural",IF(ISNUMBER(SEARCH("-ME-",D16)),"Mechanical",IF(ISNUMBER(SEARCH("-EL-",D16)),"Electrical",IF(ISNUMBER(SEARCH("-GE-",D16)),"General","Other"))))))))))) -> Electrical | R16: =IF(F16="","",IFERROR(IF(ISNUMBER(F16),F16,DATEVALUE(F16)),"")) -> 46233
B17: HAC-RFI-000119 | C17: 0 | D17: P1000-K03206-HA-HI-GE-RFI-000012 | E17: P1000-K03206-HA-HI-EL-RFI-000012 for Mockup's Voice and Data Shopdrawing Requirement (3BR VIP suit mockup). | F17: 46233 | I17: HillInt-RFI-000897 | J17: 46248 | O17: open | Q17: =IF(COUNTA(A17:P17)=0,"",IF(ISNUMBER(SEARCH("-AR-",E17)),"Architectural",IF(ISNUMBER(SEARCH("-ST-",E17)),"Structural",IF(ISNUMBER(SEARCH("-ME-",E17)),"Mechanical",IF(ISNUMBER(SEARCH("-EL-",E17)),"Electrical",IF(ISNUMBER(SEARCH("-GE-",E17)),"General",IF(ISNUMBER(SEARCH("-AR-",D17)),"Architectural",IF(ISNUMBER(SEARCH("-ST-",D17)),"Structural",IF(ISNUMBER(SEARCH("-ME-",D17)),"Mechanical",IF(ISNUMBER(SEARCH("-EL-",D17)),"Electrical",IF(ISNUMBER(SEARCH("-GE-",D17)),"General","Other"))))))))))) -> Electrical | R17: =IF(F17="","",IFERROR(IF(ISNUMBER(F17),F17,DATEVALUE(F17)),"")) -> 46233
B18: HAC-RFI-000120 | C18: 0 | D18: P1000-K03206-HA-HI-GE-RFI-000013 | E18: P1000-K03206-HA-HI-EL-RFI-000013 for Mockup's Fire Alarm Shop drawing Requirement (3BR VIP suit mockup). | F18: 46233 | I18: HillInt-RFI-000898 | J18: 46248 | O18: open | Q18: =IF(COUNTA(A18:P18)=0,"",IF(ISNUMBER(SEARCH("-AR-",E18)),"Architectural",IF(ISNUMBER(SEARCH("-ST-",E18)),"Structural",IF(ISNUMBER(SEARCH("-ME-",E18)),"Mechanical",IF(ISNUMBER(SEARCH("-EL-",E18)),"Electrical",IF(ISNUMBER(SEARCH("-GE-",E18)),"General",IF(ISNUMBER(SEARCH("-AR-",D18)),"Architectural",IF(ISNUMBER(SEARCH("-ST-",D18)),"Structural",IF(ISNUMBER(SEARCH("-ME-",D18)),"Mechanical",IF(ISNUMBER(SEARCH("-EL-",D18)),"Electrical",IF(ISNUMBER(SEARCH("-GE-",D18)),"General","Other"))))))))))) -> Electrical | R18: =IF(F18="","",IFERROR(IF(ISNUMBER(F18),F18,DATEVALUE(F18)),"")) -> 46233
B19: HAC-RFI-000121 | C19: 0 | D19: P1000-K03206-HA-HI-GE-RFI-000014 | E19: P1000-K03206-HA-HI-EL-RFI-000014 for Mockup's Power Shop drawing Requirement (3BR VIP suit mockup). | F19: 46233 | I19: HillInt-RFI-000899 | J19: 46248 | O19: open | Q19: =IF(COUNTA(A19:P19)=0,"",IF(ISNUMBER(SEARCH("-AR-",E19)),"Architectural",IF(ISNUMBER(SEARCH("-ST-",E19)),"Structural",IF(ISNUMBER(SEARCH("-ME-",E19)),"Mechanical",IF(ISNUMBER(SEARCH("-EL-",E19)),"Electrical",IF(ISNUMBER(SEARCH("-GE-",E19)),"General",IF(ISNUMBER(SEARCH("-AR-",D19)),"Architectural",IF(ISNUMBER(SEARCH("-ST-",D19)),"Structural",IF(ISNUMBER(SEARCH("-ME-",D19)),"Mechanical",IF(ISNUMBER(SEARCH("-EL-",D19)),"Electrical",IF(ISNUMBER(SEARCH("-GE-",D19)),"General","Other"))))))))))) -> Electrical | R19: =IF(F19="","",IFERROR(IF(ISNUMBER(F19),F19,DATEVALUE(F19)),"")) -> 46233
B20: HAC-RFI-000122 | C20: 0 | D20: P1000-K03206-HA-HI-GE-RFI-000015 | E20: P1000-K03206-HA-HI-ST-RFI-000015 for Clarification of Structural Reinforcement Details - DP06 project–Villa Type ( A&D). | F20: 46233 | I20: HillInt-RFI-000876 | J20: 46243 | M20: HillInt-RTCL-001037 | N20: 46248 | O20: Response | Q20: =IF(COUNTA(A20:P20)=0,"",IF(ISNUMBER(SEARCH("-AR-",E20)),"Architectural",IF(ISNUMBER(SEARCH("-ST-",E20)),"Structural",IF(ISNUMBER(SEARCH("-ME-",E20)),"Mechanical",IF(ISNUMBER(SEARCH("-EL-",E20)),"Electrical",IF(ISNUMBER(SEARCH("-GE-",E20)),"General",IF(ISNUMBER(SEARCH("-AR-",D20)),"Architectural",IF(ISNUMBER(SEARCH("-ST-",D20)),"Structural",IF(ISNUMBER(SEARCH("-ME-",D20)),"Mechanical",IF(ISNUMBER(SEARCH("-EL-",D20)),"Electrical",IF(ISNUMBER(SEARCH("-GE-",D20)),"General","Other"))))))))))) -> Structural | R20: =IF(F20="","",IFERROR(IF(ISNUMBER(F20),F20,DATEVALUE(F20)),"")) -> 46233
B21: HAC-RFI-000123 | C21: 0 | D21: P1000-K03206-HA-HI-GE-RFI-000016 | E21: P1000-K03206-HA-HI-ME-RFI-000016 for 3BR VIP Suite Type 1 Guest Room Mockup (drainage plan). | F21: 46236 | I21: HillInt-RFI-000900 | J21: 46248 | O21: open | Q21: =IF(COUNTA(A21:P21)=0,"",IF(ISNUMBER(SEARCH("-AR-",E21)),"Architectural",IF(ISNUMBER(SEARCH("-ST-",E21)),"Structural",IF(ISNUMBER(SEARCH("-ME-",E21)),"Mechanical",IF(ISNUMBER(SEARCH("-EL-",E21)),"Electrical",IF(ISNUMBER(SEARCH("-GE-",E21)),"General",IF(ISNUMBER(SEARCH("-AR-",D21)),"Architectural",IF(ISNUMBER(SEARCH("-ST-",D21)),"Structural",IF(ISNUMBER(SEARCH("-ME-",D21)),"Mechanical",IF(ISNUMBER(SEARCH("-EL-",D21)),"Electrical",IF(ISNUMBER(SEARCH("-GE-",D21)),"General","Other"))))))))))) -> Mechanical | R21: =IF(F21="","",IFERROR(IF(ISNUMBER(F21),F21,DATEVALUE(F21)),"")) -> 46236
B22: HAC-RFI-000124 | C22: 0 | D22: P1000-K03206-HA-HI-GE-RFI-000017 | E22: P1000-K03206-HA-HI-ME-RFI-000017 for 3BR VIP Suite Type 1 Guest Room Mockup (fire protection systems plan) | F22: 46236 | I22: HillInt-RFI-000901 | J22: 46248 | O22: open | Q22: =IF(COUNTA(A22:P22)=0,"",IF(ISNUMBER(SEARCH("-AR-",E22)),"Architectural",IF(ISNUMBER(SEARCH("-ST-",E22)),"Structural",IF(ISNUMBER(SEARCH("-ME-",E22)),"Mechanical",IF(ISNUMBER(SEARCH("-EL-",E22)),"Electrical",IF(ISNUMBER(SEARCH("-GE-",E22)),"General",IF(ISNUMBER(SEARCH("-AR-",D22)),"Architectural",IF(ISNUMBER(SEARCH("-ST-",D22)),"Structural",IF(ISNUMBER(SEARCH("-ME-",D22)),"Mechanical",IF(ISNUMBER(SEARCH("-EL-",D22)),"Electrical",IF(ISNUMBER(SEARCH("-GE-",D22)),"General","Other"))))))))))) -> Mechanical | R22: =IF(F22="","",IFERROR(IF(ISNUMBER(F22),F22,DATEVALUE(F22)),"")) -> 46236
B23: HAC-RFI-000125 | C23: 0 | D23: P1000-K03206-HA-HI-GE-RFI-000018 | E23: P1000-K03206-HA-HI-ME-RFI-000018 for 3BR VIP Suite Type 1 Guest Room Mockup (HVAC plan). | F23: 46236 | I23: HillInt-RFI-000902 | J23: 46248 | O23: open | Q23: =IF(COUNTA(A23:P23)=0,"",IF(ISNUMBER(SEARCH("-AR-",E23)),"Architectural",IF(ISNUMBER(SEARCH("-ST-",E23)),"Structural",IF(ISNUMBER(SEARCH("-ME-",E23)),"Mechanical",IF(ISNUMBER(SEARCH("-EL-",E23)),"Electrical",IF(ISNUMBER(SEARCH("-GE-",E23)),"General",IF(ISNUMBER(SEARCH("-AR-",D23)),"Architectural",IF(ISNUMBER(SEARCH("-ST-",D23)),"Structural",IF(ISNUMBER(SEARCH("-ME-",D23)),"Mechanical",IF(ISNUMBER(SEARCH("-EL-",D23)),"Electrical",IF(ISNUMBER(SEARCH("-GE-",D23)),"General","Other"))))))))))) -> Mechanical | R23: =IF(F23="","",IFERROR(IF(ISNUMBER(F23),F23,DATEVALUE(F23)),"")) -> 46236
B24: HAC-RFI-000126 | C24: 0 | D24: P1000-K03206-HA-HI-GE-RFI-000019 | E24: P1000-K03206-HA-HI-ME-RFI-000019 for 3BR VIP Suite Type 1 ater supply systems plan).Guest Room Mockup (w | F24: 46236 | I24: HillInt-RFI-000903 | J24: 46248 | O24: open | Q24: =IF(COUNTA(A24:P24)=0,"",IF(ISNUMBER(SEARCH("-AR-",E24)),"Architectural",IF(ISNUMBER(SEARCH("-ST-",E24)),"Structural",IF(ISNUMBER(SEARCH("-ME-",E24)),"Mechanical",IF(ISNUMBER(SEARCH("-EL-",E24)),"Electrical",IF(ISNUMBER(SEARCH("-GE-",E24)),"General",IF(ISNUMBER(SEARCH("-AR-",D24)),"Architectural",IF(ISNUMBER(SEARCH("-ST-",D24)),"Structural",IF(ISNUMBER(SEARCH("-ME-",D24)),"Mechanical",IF(ISNUMBER(SEARCH("-EL-",D24)),"Electrical",IF(ISNUMBER(SEARCH("-GE-",D24)),"General","Other"))))))))))) -> Mechanical | R24: =IF(F24="","",IFERROR(IF(ISNUMBER(F24),F24,DATEVALUE(F24)),"")) -> 46236
B25: HAC-RFI-000127 | C25: 0 | D25: P1000-K03206-HA-HI-GE-RFI-000020 | E25: P1000-K03206-HA-HI-AR-RFI-000020 For Conflicts Between Structural IFC and Architectural Schematic Design. | F25: 46236 | I25: HillInt-RFI-000877 | J25: 9 August 2026 | M25: HillInt-RTCL-001036 | N25: 46248 | O25: Response | Q25: =IF(COUNTA(A25:P25)=0,"",IF(ISNUMBER(SEARCH("-AR-",E25)),"Architectural",IF(ISNUMBER(SEARCH("-ST-",E25)),"Structural",IF(ISNUMBER(SEARCH("-ME-",E25)),"Mechanical",IF(ISNUMBER(SEARCH("-EL-",E25)),"Electrical",IF(ISNUMBER(SEARCH("-GE-",E25)),"General",IF(ISNUMBER(SEARCH("-AR-",D25)),"Architectural",IF(ISNUMBER(SEARCH("-ST-",D25)),"Structural",IF(ISNUMBER(SEARCH("-ME-",D25)),"Mechanical",IF(ISNUMBER(SEARCH("-EL-",D25)),"Electrical",IF(ISNUMBER(SEARCH("-GE-",D25)),"General","Other"))))))))))) -> Architectural | R25: =IF(F25="","",IFERROR(IF(ISNUMBER(F25),F25,DATEVALUE(F25)),"")) -> 46236
B26: HAC-RFI-000130 | C26: 0 | D26: P1000-K03206-HA-HI-GE-RFI-000021 | E26: P1000-K03206-HA-HI-ST-RFI-000021-00 For Conflict Between Excavation IFC and Structural IFC for Villas | F26: 46242 | I26: HillInt-RFI-000878 | J26: 46273 | M26: HillInt-RTCL-001038 | N26: 14/08/2026 | O26: Response | Q26: =IF(COUNTA(A26:P26)=0,"",IF(ISNUMBER(SEARCH("-AR-",E26)),"Architectural",IF(ISNUMBER(SEARCH("-ST-",E26)),"Structural",IF(ISNUMBER(SEARCH("-ME-",E26)),"Mechanical",IF(ISNUMBER(SEARCH("-EL-",E26)),"Electrical",IF(ISNUMBER(SEARCH("-GE-",E26)),"General",IF(ISNUMBER(SEARCH("-AR-",D26)),"Architectural",IF(ISNUMBER(SEARCH("-ST-",D26)),"Structural",IF(ISNUMBER(SEARCH("-ME-",D26)),"Mechanical",IF(ISNUMBER(SEARCH("-EL-",D26)),"Electrical",IF(ISNUMBER(SEARCH("-GE-",D26)),"General","Other"))))))))))) -> Structural | R26: =IF(F26="","",IFERROR(IF(ISNUMBER(F26),F26,DATEVALUE(F26)),"")) -> 46242
B27: HAC-RFI-000131 | C27: 0 | D27: P1000-K03206-HA-HI-GE-RFI-000022 | E27: P1000-K03206-HA-HI-ST-RFI-000022-00 For Missing Stair Starter Details in Villas Foundation IFC. | F27: 46237 | I27: HillInt-RFI-000879 | J27: 46243 | M27: HillInt-RTCL-001039 | N27: 14/08/2026 | O27: Response | Q27: =IF(COUNTA(A27:P27)=0,"",IF(ISNUMBER(SEARCH("-AR-",E27)),"Architectural",IF(ISNUMBER(SEARCH("-ST-",E27)),"Structural",IF(ISNUMBER(SEARCH("-ME-",E27)),"Mechanical",IF(ISNUMBER(SEARCH("-EL-",E27)),"Electrical",IF(ISNUMBER(SEARCH("-GE-",E27)),"General",IF(ISNUMBER(SEARCH("-AR-",D27)),"Architectural",IF(ISNUMBER(SEARCH("-ST-",D27)),"Structural",IF(ISNUMBER(SEARCH("-ME-",D27)),"Mechanical",IF(ISNUMBER(SEARCH("-EL-",D27)),"Electrical",IF(ISNUMBER(SEARCH("-GE-",D27)),"General","Other"))))))))))) -> Structural | R27: =IF(F27="","",IFERROR(IF(ISNUMBER(F27),F27,DATEVALUE(F27)),"")) -> 46237
B28: HAC-RFI-000132 | C28: 0 | D28: P1000-K03206-HA-HI-GE-RFI-000023 | E28: P1000-K03206-HA-HI-ST-RFI-000023-00 For Conflict Between BOQ and IFC Concrete Grade | F28: 46237 | I28: HillInt-RFI-000880 | J28: 46243 | M28: HillInt-RTCL-001035 | N28: 14/08/2026 | O28: Response | Q28: =IF(COUNTA(A28:P28)=0,"",IF(ISNUMBER(SEARCH("-AR-",E28)),"Architectural",IF(ISNUMBER(SEARCH("-ST-",E28)),"Structural",IF(ISNUMBER(SEARCH("-ME-",E28)),"Mechanical",IF(ISNUMBER(SEARCH("-EL-",E28)),"Electrical",IF(ISNUMBER(SEARCH("-GE-",E28)),"General",IF(ISNUMBER(SEARCH("-AR-",D28)),"Architectural",IF(ISNUMBER(SEARCH("-ST-",D28)),"Structural",IF(ISNUMBER(SEARCH("-ME-",D28)),"Mechanical",IF(ISNUMBER(SEARCH("-EL-",D28)),"Electrical",IF(ISNUMBER(SEARCH("-GE-",D28)),"General","Other"))))))))))) -> Structural | R28: =IF(F28="","",IFERROR(IF(ISNUMBER(F28),F28,DATEVALUE(F28)),"")) -> 46237
B29: HAC-RFI-000166 | C29: 1 | D29: P1000-K03206-HA-HI-GE-RFI-000023 | E29: P1000-K03206-HA-HI-ST-RFI-000023-00 For Conflict Between BOQ and IFC Concrete Grade | F29: 46253 | I29: HillInt-RFI-001013 | J29: 46253 | M29: HillInt-RTCL-001138 | N29: 46258 | O29: Response | Q29: =IF(COUNTA(A29:P29)=0,"",IF(ISNUMBER(SEARCH("-AR-",E29)),"Architectural",IF(ISNUMBER(SEARCH("-ST-",E29)),"Structural",IF(ISNUMBER(SEARCH("-ME-",E29)),"Mechanical",IF(ISNUMBER(SEARCH("-EL-",E29)),"Electrical",IF(ISNUMBER(SEARCH("-GE-",E29)),"General",IF(ISNUMBER(SEARCH("-AR-",D29)),"Architectural",IF(ISNUMBER(SEARCH("-ST-",D29)),"Structural",IF(ISNUMBER(SEARCH("-ME-",D29)),"Mechanical",IF(ISNUMBER(SEARCH("-EL-",D29)),"Electrical",IF(ISNUMBER(SEARCH("-GE-",D29)),"General","Other"))))))))))) -> Structural | R29: =IF(F29="","",IFERROR(IF(ISNUMBER(F29),F29,DATEVALUE(F29)),"")) -> 46253
B30: HAC-RFI-000133 | C30: 0 | D30: P1000-K03206-HA-HI-GE-RFI-000024 | E30: P1000-K03206-HA-HI-AR-RFI-000024-00 For Hotel Room Mock-Up Selection. | F30: 46237 | G30: HillInt-RFI-000904 | H30: 46246 | I30: HillInt-RFI-000904 | J30: 46246 | O30: open | Q30: =IF(COUNTA(A30:P30)=0,"",IF(ISNUMBER(SEARCH("-AR-",E30)),"Architectural",IF(ISNUMBER(SEARCH("-ST-",E30)),"Structural",IF(ISNUMBER(SEARCH("-ME-",E30)),"Mechanical",IF(ISNUMBER(SEARCH("-EL-",E30)),"Electrical",IF(ISNUMBER(SEARCH("-GE-",E30)),"General",IF(ISNUMBER(SEARCH("-AR-",D30)),"Architectural",IF(ISNUMBER(SEARCH("-ST-",D30)),"Structural",IF(ISNUMBER(SEARCH("-ME-",D30)),"Mechanical",IF(ISNUMBER(SEARCH("-EL-",D30)),"Electrical",IF(ISNUMBER(SEARCH("-GE-",D30)),"General","Other"))))))))))) -> Architectural | R30: =IF(F30="","",IFERROR(IF(ISNUMBER(F30),F30,DATEVALUE(F30)),"")) -> 46237
B31: HAC-RFI-000134 | C31: 0 | D31: P1000-K03206-HA-HI-GE-RFI-000025 | E31: P1000-K03206-HA-HI-AR-RFI-000025-00 For Missing Details for ID Build-Up Wall Types for Hotel Room Mock-Up. | F31: 46237 | G31: HillInt-RFI-000905 | H31: 46246 | I31: HillInt-RFI-000905 | J31: 46246 | O31: open | Q31: =IF(COUNTA(A31:P31)=0,"",IF(ISNUMBER(SEARCH("-AR-",E31)),"Architectural",IF(ISNUMBER(SEARCH("-ST-",E31)),"Structural",IF(ISNUMBER(SEARCH("-ME-",E31)),"Mechanical",IF(ISNUMBER(SEARCH("-EL-",E31)),"Electrical",IF(ISNUMBER(SEARCH("-GE-",E31)),"General",IF(ISNUMBER(SEARCH("-AR-",D31)),"Architectural",IF(ISNUMBER(SEARCH("-ST-",D31)),"Structural",IF(ISNUMBER(SEARCH("-ME-",D31)),"Mechanical",IF(ISNUMBER(SEARCH("-EL-",D31)),"Electrical",IF(ISNUMBER(SEARCH("-GE-",D31)),"General","Other"))))))))))) -> Architectural | R31: =IF(F31="","",IFERROR(IF(ISNUMBER(F31),F31,DATEVALUE(F31)),"")) -> 46237
B32: HAC-RFI-000135 | C32: 0 | D32: P1000-K03206-HA-HI-GE-RFI-000026 | E32: P1000-K03206-HA-HI-AR-RFI-000026-00 for Conflict Between Architectural and Interior Drawings – Hotel Room Mock-Up. | F32: 46237 | G32: HillInt-RFI-000906 | H32: 46246 | I32: HillInt-RFI-000906 | J32: 46246 | O32: open | Q32: =IF(COUNTA(A32:P32)=0,"",IF(ISNUMBER(SEARCH("-AR-",E32)),"Architectural",IF(ISNUMBER(SEARCH("-ST-",E32)),"Structural",IF(ISNUMBER(SEARCH("-ME-",E32)),"Mechanical",IF(ISNUMBER(SEARCH("-EL-",E32)),"Electrical",IF(ISNUMBER(SEARCH("-GE-",E32)),"General",IF(ISNUMBER(SEARCH("-AR-",D32)),"Architectural",IF(ISNUMBER(SEARCH("-ST-",D32)),"Structural",IF(ISNUMBER(SEARCH("-ME-",D32)),"Mechanical",IF(ISNUMBER(SEARCH("-EL-",D32)),"Electrical",IF(ISNUMBER(SEARCH("-GE-",D32)),"General","Other"))))))))))) -> Architectural | R32: =IF(F32="","",IFERROR(IF(ISNUMBER(F32),F32,DATEVALUE(F32)),"")) -> 46237
B33: HAC-RFI-000136 | C33: 0 | D33: P1000-K03206-HA-HI-GE-RFI-000027 | E33: P1000-K03206-HA-HI-AR-RFI-000027-00 for Missing Architectural Opening Details for Hotel Room Mock-Up. | F33: 46237 | G33: HillInt-RFI-000907 | H33: 46246 | I33: HillInt-RFI-000907 | J33: 46246 | O33: open | Q33: =IF(COUNTA(A33:P33)=0,"",IF(ISNUMBER(SEARCH("-AR-",E33)),"Architectural",IF(ISNUMBER(SEARCH("-ST-",E33)),"Structural",IF(ISNUMBER(SEARCH("-ME-",E33)),"Mechanical",IF(ISNUMBER(SEARCH("-EL-",E33)),"Electrical",IF(ISNUMBER(SEARCH("-GE-",E33)),"General",IF(ISNUMBER(SEARCH("-AR-",D33)),"Architectural",IF(ISNUMBER(SEARCH("-ST-",D33)),"Structural",IF(ISNUMBER(SEARCH("-ME-",D33)),"Mechanical",IF(ISNUMBER(SEARCH("-EL-",D33)),"Electrical",IF(ISNUMBER(SEARCH("-GE-",D33)),"General","Other"))))))))))) -> Architectural | R33: =IF(F33="","",IFERROR(IF(ISNUMBER(F33),F33,DATEVALUE(F33)),"")) -> 46237
B34: HAC-RFI-000137 | C34: 0 | D34: P1000-K03206-HA-HI-GE-RFI-000028 | E34: P1000-K03206-HA-HI-ST-RFI-000028-00 for Construction sequence for DP06 project – All Villa’s. | F34: 46237 | G34: HillInt-RFI-000908 | H34: 46246 | I34: HillInt-RFI-000908 | J34: 46246 | M34: HillInt-RTCL-001040 | N34: 46248 | O34: Response | Q34: =IF(COUNTA(A34:P34)=0,"",IF(ISNUMBER(SEARCH("-AR-",E34)),"Architectural",IF(ISNUMBER(SEARCH("-ST-",E34)),"Structural",IF(ISNUMBER(SEARCH("-ME-",E34)),"Mechanical",IF(ISNUMBER(SEARCH("-EL-",E34)),"Electrical",IF(ISNUMBER(SEARCH("-GE-",E34)),"General",IF(ISNUMBER(SEARCH("-AR-",D34)),"Architectural",IF(ISNUMBER(SEARCH("-ST-",D34)),"Structural",IF(ISNUMBER(SEARCH("-ME-",D34)),"Mechanical",IF(ISNUMBER(SEARCH("-EL-",D34)),"Electrical",IF(ISNUMBER(SEARCH("-GE-",D34)),"General","Other"))))))))))) -> Structural | R34: =IF(F34="","",IFERROR(IF(ISNUMBER(F34),F34,DATEVALUE(F34)),"")) -> 46237
B35: HAC-RFI-000203 | C35: 1 | D35: P1000-K03206-HA-HI-GE-RFI-000028 | E35: P1000-K03206-HA-HI-ST-RFI-000028-00 for Construction sequence for DP06 project – All Villa’s. | F35: 46274 | I35: HillInt-GNC-003454 | J35: 46275 | O35: open | Q35: =IF(COUNTA(A35:P35)=0,"",IF(ISNUMBER(SEARCH("-AR-",E35)),"Architectural",IF(ISNUMBER(SEARCH("-ST-",E35)),"Structural",IF(ISNUMBER(SEARCH("-ME-",E35)),"Mechanical",IF(ISNUMBER(SEARCH("-EL-",E35)),"Electrical",IF(ISNUMBER(SEARCH("-GE-",E35)),"General",IF(ISNUMBER(SEARCH("-AR-",D35)),"Architectural",IF(ISNUMBER(SEARCH("-ST-",D35)),"Structural",IF(ISNUMBER(SEARCH("-ME-",D35)),"Mechanical",IF(ISNUMBER(SEARCH("-EL-",D35)),"Electrical",IF(ISNUMBER(SEARCH("-GE-",D35)),"General","Other"))))))))))) -> Structural | R35: =IF(F35="","",IFERROR(IF(ISNUMBER(F35),F35,DATEVALUE(F35)),"")) -> 46274
B36: HAC-RFI-000144 | C36: 0 | D36: P1000-K03206-HA-HI-GE-RFI-000029 | E36: P1000-K03206-HA-HI-AR-RFI-000029-00 for Villa Mockup Location as per site condition DP6-Villas. | F36: 46239 | G36: HillInt-RFI-000909 | H36: 46246 | I36: HillInt-RFI-000909 | J36: 46246 | O36: open | Q36: =IF(COUNTA(A36:P36)=0,"",IF(ISNUMBER(SEARCH("-AR-",E36)),"Architectural",IF(ISNUMBER(SEARCH("-ST-",E36)),"Structural",IF(ISNUMBER(SEARCH("-ME-",E36)),"Mechanical",IF(ISNUMBER(SEARCH("-EL-",E36)),"Electrical",IF(ISNUMBER(SEARCH("-GE-",E36)),"General",IF(ISNUMBER(SEARCH("-AR-",D36)),"Architectural",IF(ISNUMBER(SEARCH("-ST-",D36)),"Structural",IF(ISNUMBER(SEARCH("-ME-",D36)),"Mechanical",IF(ISNUMBER(SEARCH("-EL-",D36)),"Electrical",IF(ISNUMBER(SEARCH("-GE-",D36)),"General","Other"))))))))))) -> Architectural | R36: =IF(F36="","",IFERROR(IF(ISNUMBER(F36),F36,DATEVALUE(F36)),"")) -> 46239
B37: HAC-RFI-000155 | C37: 0 | D37: P1000-K03206-HA-HI-GE-RFI-000030 | E37: P1000-K03206-HA-HI-ST-RFI-000030 for Confirmation of Lift Type and Lift Pit Dimensions & Levels. (DP06 project – All Villa’s) | F37: 46247 | I37: HillInt-RFI-000916 | J37: 14 August 202 | M37: HillInt-RTCL-001082 | N37: 46253 | O37: Response | Q37: =IF(COUNTA(A37:P37)=0,"",IF(ISNUMBER(SEARCH("-AR-",E37)),"Architectural",IF(ISNUMBER(SEARCH("-ST-",E37)),"Structural",IF(ISNUMBER(SEARCH("-ME-",E37)),"Mechanical",IF(ISNUMBER(SEARCH("-EL-",E37)),"Electrical",IF(ISNUMBER(SEARCH("-GE-",E37)),"General",IF(ISNUMBER(SEARCH("-AR-",D37)),"Architectural",IF(ISNUMBER(SEARCH("-ST-",D37)),"Structural",IF(ISNUMBER(SEARCH("-ME-",D37)),"Mechanical",IF(ISNUMBER(SEARCH("-EL-",D37)),"Electrical",IF(ISNUMBER(SEARCH("-GE-",D37)),"General","Other"))))))))))) -> Structural | R37: =IF(F37="","",IFERROR(IF(ISNUMBER(F37),F37,DATEVALUE(F37)),"")) -> 46247
B38: HAC-RFI-000156 | C38: 0 | D38: P1000-K03206-HA-HI-GE-RFI-000031 | E38: P1000-K03206-HA-HI-ST-RFI-000031 for Clarification on Villa Type Discrepancy in Villas IFC Excavation Drawings. (DP06 project – All Villa’s) | F38: 46247 | I38: HillInt-RFI-000917 | J38: 14 August 202 | M38: HillInt-RTCL-001083 | N38: 46253 | O38: Response | Q38: =IF(COUNTA(A38:P38)=0,"",IF(ISNUMBER(SEARCH("-AR-",E38)),"Architectural",IF(ISNUMBER(SEARCH("-ST-",E38)),"Structural",IF(ISNUMBER(SEARCH("-ME-",E38)),"Mechanical",IF(ISNUMBER(SEARCH("-EL-",E38)),"Electrical",IF(ISNUMBER(SEARCH("-GE-",E38)),"General",IF(ISNUMBER(SEARCH("-AR-",D38)),"Architectural",IF(ISNUMBER(SEARCH("-ST-",D38)),"Structural",IF(ISNUMBER(SEARCH("-ME-",D38)),"Mechanical",IF(ISNUMBER(SEARCH("-EL-",D38)),"Electrical",IF(ISNUMBER(SEARCH("-GE-",D38)),"General","Other"))))))))))) -> Structural | R38: =IF(F38="","",IFERROR(IF(ISNUMBER(F38),F38,DATEVALUE(F38)),"")) -> 46247
B39: HAC-RFI-000160 | C39: 0 | D39: P1000-K03206-HA-HI-ST-RFI-000032 | E39: P1000-K03206-HA-HI-ST-RFI-000032 for Foundation Level Conflict in IFC Foundation Package (DP06 project – All Villas) | F39: 46247 | I39: HillInt-RFI-000918 | J39: 14 August 202 | M39: HillInt-RTCL-001084 | N39: 46253 | O39: Response | Q39: =IF(COUNTA(A39:P39)=0,"",IF(ISNUMBER(SEARCH("-AR-",E39)),"Architectural",IF(ISNUMBER(SEARCH("-ST-",E39)),"Structural",IF(ISNUMBER(SEARCH("-ME-",E39)),"Mechanical",IF(ISNUMBER(SEARCH("-EL-",E39)),"Electrical",IF(ISNUMBER(SEARCH("-GE-",E39)),"General",IF(ISNUMBER(SEARCH("-AR-",D39)),"Architectural",IF(ISNUMBER(SEARCH("-ST-",D39)),"Structural",IF(ISNUMBER(SEARCH("-ME-",D39)),"Mechanical",IF(ISNUMBER(SEARCH("-EL-",D39)),"Electrical",IF(ISNUMBER(SEARCH("-GE-",D39)),"General","Other"))))))))))) -> Structural | R39: =IF(F39="","",IFERROR(IF(ISNUMBER(F39),F39,DATEVALUE(F39)),"")) -> 46247
B40: HAC-RFI-000159 | C40: 0 | D40: P1000-K03206-HA-HI-ST-RFI-000033 | E40: P1000-K03206-HA-HI-ST-RFI-000033 for Foundation Level Conflict in IFC Foundation Package (DP06 project – villa type A & B) | F40: 46247 | I40: HillInt-RFI-000919 | J40: 46248 | M40: HillInt-RTCL-001085 | N40: 46253 | O40: Response | Q40: =IF(COUNTA(A40:P40)=0,"",IF(ISNUMBER(SEARCH("-AR-",E40)),"Architectural",IF(ISNUMBER(SEARCH("-ST-",E40)),"Structural",IF(ISNUMBER(SEARCH("-ME-",E40)),"Mechanical",IF(ISNUMBER(SEARCH("-EL-",E40)),"Electrical",IF(ISNUMBER(SEARCH("-GE-",E40)),"General",IF(ISNUMBER(SEARCH("-AR-",D40)),"Architectural",IF(ISNUMBER(SEARCH("-ST-",D40)),"Structural",IF(ISNUMBER(SEARCH("-ME-",D40)),"Mechanical",IF(ISNUMBER(SEARCH("-EL-",D40)),"Electrical",IF(ISNUMBER(SEARCH("-GE-",D40)),"General","Other"))))))))))) -> Structural | R40: =IF(F40="","",IFERROR(IF(ISNUMBER(F40),F40,DATEVALUE(F40)),"")) -> 46247
...
