Workbook
Name Action: #REF!
Name Buidling: #REF!
Name Discipline: #REF!
Name Level: #REF!
Name Type: #REF!

Sheet Dashboard
A1: SITE CLARIFICATION LOG DASHBOARD DP01
A3: Automatic summary of Pending and Responded items for every sheet
A5: TOTAL ITEMS | D5: PENDING | G5: RESPONDED
A7: =B17 -> 1709 | D7: =C17 -> 95 | G7: =D17 -> 1614
A10: Sheet Name | B10: Total | C10: Pending | D10: Responded | E10: Response Rate
A11: GN | B11: =COUNTIF(GN!K5:K10000,"Pending")+COUNTIF(GN!K5:K10000,"Responded") -> 14 | C11: =COUNTIF(GN!K5:K10000,"Pending") -> 3 | D11: =COUNTIF(GN!K5:K10000,"Responded") -> 11 | E11: =IF(B11=0,0,D11/B11) -> 0.78571429
A12: ST | B12: =COUNTIF(ST!K5:K9999,"Pending")+COUNTIF(ST!K5:K9999,"Responded") -> 963 | C12: =COUNTIF(ST!K5:K9999,"Pending") -> 36 | D12: =COUNTIF(ST!K5:K9999,"Responded") -> 927 | E12: =IF(B12=0,0,D12/B12) -> 0.96261682
A13: AR | B13: =COUNTIF(AR!K5:K60,"Pending")+COUNTIF(AR!K5:K60,"Responded") -> 56 | C13: =COUNTIF(AR!K5:K60,"Pending") -> 6 | D13: =COUNTIF(AR!K5:K60,"Responded") -> 50 | E13: =IF(B13=0,0,D13/B13) -> 0.89285714
A14: EL | B14: =COUNTIF(EL!K5:K10000,"Pending")+COUNTIF(EL!K5:K10000,"Responded") -> 352 | C14: =COUNTIF(EL!K5:K10000,"Pending") -> 22 | D14: =COUNTIF(EL!K5:K10000,"Responded") -> 330 | E14: =IF(B14=0,0,D14/B14) -> 0.9375
A15: ME | B15: =COUNTIF(ME!K5:K9999,"Pending")+COUNTIF(ME!K5:K9999,"Responded") -> 303 | C15: =COUNTIF(ME!K5:K9999,"Pending") -> 25 | D15: =COUNTIF(ME!K5:K9999,"Responded") -> 278 | E15: =IF(B15=0,0,D15/B15) -> 0.91749175
A16: Telecom | B16: =COUNTIF(Telecom!H5:H9999,"Pending")+COUNTIF(Telecom!H5:H9999,"Responded") -> 21 | C16: =COUNTIF(Telecom!H5:H9999,"Pending") -> 3 | D16: =COUNTIF(Telecom!H5:H9999,"Responded") -> 18 | E16: =IF(B16=0,0,D16/B16) -> 0.85714286
A17: GRAND TOTAL | B17: =SUM(B11:B16) -> 1709 | C17: =SUM(C11:C16) -> 95 | D17: =SUM(D11:D16) -> 1614 | E17: =IF(B17=0,0,D17/B17) -> 0.94441194
A23: GN | D23: ST | G23: AR
A24: Total | B24: =B11 -> 14 | D24: Total | E24: =B12 -> 963 | G24: Total | H24: =B13 -> 56
A25: Pending | B25: =C11 -> 3 | D25: Pending | E25: =C12 -> 36 | G25: Pending | H25: =C13 -> 6
A26: Responded | B26: =D11 -> 11 | D26: Responded | E26: =D12 -> 927 | G26: Responded | H26: =D13 -> 50
A28: EL | D28: ME | G28: Telecom
A29: Total | B29: =B14 -> 352 | D29: Total | E29: =B15 -> 303 | G29: Total | H29: =B16 -> 21
A30: Pending | B30: =C14 -> 22 | D30: Pending | E30: =C15 -> 25 | G30: Pending | H30: =C16 -> 3
A31: Responded | B31: =D14 -> 330 | D31: Responded | E31: =D15 -> 278 | G31: Responded | H31: =D16 -> 18

Sheet GN
G2: Site Clarification Request ( General )
D4: Ref. | E4: Mail No | F4: Rev. | G4: Subject | H4: Sub-Building | I4: Issue Date | J4: Received Date | K4: Action
D5: REH-MD01-MDU-ZZ-OC-Hil-1025-SCR-000001 | E5: REH-MD01-ZZ-OC-Hil-1025-SCR-01 | F5: 0 | G5: REH-MDU - Wadi Yemm - Missing data for Apartments Arch & MEP 50% DD Package at plot 1025 | H5: 1025 | I5: 46145 | J5: 46148 | K5: Responded
D6: REH-MD01-MDU-ZZ-OC-Hil-1025-SCR-000002 | E6: OC-SCR-000589 | F6: 0 | G6: REH-MDU - Wadi Yemm - Changing the location of panel board in apartment (Q2-3) - Plot 1025 | H6: 1025 | I6: 46231 | J6: 46237 | K6: Responded
D7: REH-MD01-MDU-ZZ-OC-Hil-1044-SCR-000001 | E7: OC-SCR-000659 | F7: 0 | G7: REH-MDU - Wadi Yemm - Dropping slap in spa areas & clash beam with door | H7: 1044 | I7: 46237 | J7: 46246 | K7: Responded
D8: REH-MD01-MDU-ZZ-OC-Hil-1031-SCR-000001 | E8: OC-SCR-000690 | F8: 0 | G8: REH-MDU - Wadi Yemm - SCR – Clarification Regarding Electrical and LC Outlets and Devices Mounting Heights in the (Shaker Package) | H8: 1031 | I8: 46240 | J8: 46244 | K8: Responded
D9: REH-MD01-MDU-ZZ-OC-Hil-1031-SCR-000002 | E9: OC-SCR-000691 | F9: 0 | G9: REH-MDU - Wadi Yemm - SCR – Clarification Regarding the Mounting Heights of Electrical and ELV Devices Inside the Elevator Shaft (Shaker Package | H9: 1031 | I9: 46240 | J9: 46245 | K9: Responded
D10: REH-MD01-MDU-ZZ-OC-Hil-1044-SCR-000002 | E10: OC-SCR-000713 | F10: 0 | G10: REH-MDU - Wadi Yemm - beam with wall arch & clash wall arch & str | H10: 1044 | I10: 46243 | J10: 46251 | K10: Responded
D11: REH-MD01-MDU-ZZ-OC-Hil-1021-SCR-000001 | E11: OC-SCR-000731 | F11: 0 | G11: REH-MDU - Wadi Yemm - Changing the location of panel board in apartment (Q3-3BHK) - Plot 1021 | H11: 1021 | I11: 46243 | J11: 46256 | K11: Responded
D12: REH-MD01-MDU-ZZ-OC-Hil-1024-SCR-000001 | E12: OC-SCR-000791 | F12: 0 | G12: REH-MDU - Wadi Yemm - Clarification Regarding the Mounting Heights of Electrical and ELV Devices Inside the Elevator Shaft (ECG Package) | H12: 1024 | I12: 46247 | J12: 46253 | K12: Responded
D13: REH-MD01-MDU-ZZ-OC-Hil-1044-SCR-000003 | E13: OC-SCR-000954 | F13: 0 | G13: REH-MDU - Wadi Yemm - Staircase Coordination Clarification | H13: 1044 | I13: 46260 | J13: 46274 | K13: Responded
D14: REH-MD01-MDU-ZZ-OC-Hil-1025-SCR-000003 | E14: OC-SCR-001170 | F14: 0 | G14: REH-MDU - Wadi Yemm - Plot 1025- MEP Openings in beams | H14: 1025 | I14: 46280 | J14: 46281 | K14: Responded
D15: REH-MD01-MDU-ZZ-OC-Hil-1044-SCR-000004 | E15: OC-SCR-001321 | F15: 0 | G15: REH-MDU - Wadi Yemm - Column Alignment at the Slab Edge and Omission of Beam CA3 | H15: 1044 | I15: 46289 | J15: 46292 | K15: Responded
D16: REH-MD01-MDU-ZZ-OC-Hil-1021-SCR-000002 | E16: OC-SCR-001366 | F16: 0 | G16: REH-MDU - Wadi Yemm - Plot 1021 -Ground level -Attic Slab-part 04 | H16: 1021 | I16: 46295 | K16: Pending
D17: REH-MD01-MDU-SS-OC-Hil-1018-SCR-000029 | E17: OC-SCR-001419 | F17: 0 | G17: REH-MD01-MDU-SS-OC-Hil-1018-SCR-000029 - Corridor CCTV Coverage Not Complete - PLOT#1018 - FIRST FLOOR | H17: 1081 | I17: 46300 | K17: Pending
D18: REH-MD01-MDU-ZZ-OC-Hil-1031-SCR-000003 | E18: OC-SCR-001434 | F18: 0 | G18: REH-MD01-MDU-ZZ-OC-Hil-1031-SCR-000003-SP02-Plot 1031,1032,1033 FOR all typical stair RFT detail. (Missing Reinforcement Details) | H18: 1031 | I18: 46301 | K18: Pending

Sheet ST
A1: Project Name:- REH Wadi Yemm DP01 - Sea Town Center
A2: Location:- Northern coast near Ras Al Hekma Cape, Egypt. | G2: Site Clarification Request ( Structural )
A3: Employer:- Modon.
A4: Lead Consultant:- SHAKER & ECG | D4: Ref. | E4: Mail No | F4: Rev. | G4: Subject | H4: Sub-Building | I4: Issue Date | J4: Received Date | K4: Action
D5: P0155-RA06-SCR-ST-OC-DAR-000001 | F5: 0 | G5: P0155 - K00146 – REH Wadi Yemm - Sea Town Center - Missing data and discrepancy at plot 1024 | H5: RA06 | I5: 46012 | J5: 46013 | K5: Responded
D6: P0155-RA06-SCR-ST-OC-DAR-000002 | F6: 0 | G6: P0155 - K00146 – REH Wadi Yemm - Sea Town Center - Missing data and discrepancy (2) at plot 1024 | H6: RA06 | I6: 46013 | J6: 46017 | K6: Responded
D7: P0155-RA04-SCR-ST-OC-DAR-000001 | F7: 0 | G7: P0155 - K00146 – REH Wadi Yemm - Sea Town Center - Missing data and discrepancy at plot 1025 | H7: RA04 | I7: 46014 | J7: 46015 | K7: Responded
D8: P0155-RA00-SCR-ST-OC-DAR-000001 | F8: 0 | G8: P0155 - K00146 – REH Wadi Yemm - Sea Town Center - Cement Type for Concrete Materials (Wadi Yemm Project) | H8: RA00 | I8: 46014 | K8: Pending
D9: P0155-RA06-SCR-ST-OC-DAR-000003 | F9: 0 | G9: P0155 - K00146 – REH Wadi Yemm - Sea Town Center - Discrepancy Between StructuraL and Architectural Drawings plot 1024 | H9: RA06 | I9: 46016 | J9: 46018 | K9: Responded
D10: P0155-RA04-SCR-ST-OC-DAR-000002 | F10: 0 | G10: P0155 - K00146 – REH Wadi Yemm - Sea Town Center - Missing data and discrepancy (2) at plot 1025 | H10: RA04 | I10: 46018 | J10: 46020 | K10: Responded
D11: P0155-RA06-SCR-ST-OC-DAR-000004 | F11: 0 | G11: P0155 - K00146 – REH Wadi Yemm - Sea Town Center -Missing data and conflicts in columns (1) in plot 1024 | H11: RA06 | I11: 46019 | J11: 46021 | K11: Responded
D12: P0155-RA06-SCR-ST-OC-DAR-000005 | F12: 0 | G12: P0155 - K00146 – REH Wadi Yemm - Sea Town Center - Missing data and conflicts in columns (2) in plot 1024 | H12: RA06 | I12: 46019 | J12: 46021 | K12: Responded
D13: P0155-RA03-SCR-ST-OC-DAR-000001 | F13: 0 | G13: P0155 - K00146 – REH Wadi Yemm - Sea Town Center - Missing and Conflict data at plot 1047 | H13: RA03 | I13: 46027 | J13: 46033 | K13: Responded
D14: P0155-RA03-SCR-ST-OC-DAR-000002 | F14: 0 | G14: P0155 - K00146 – REH Wadi Yemm - Sea Town Center - Missing and Conflict data at plot 1047 | H14: RA03 | I14: 46032 | J14: 46033 | K14: Responded
D15: P0155-RA06-SCR-ST-OC-DAR-000006 | F15: 0 | G15: P0155 - K00146 – REH Wadi Yemm - Sea Town Center - Missing data and conflicts in columns in plot 1024 | H15: RA06 | I15: 46034 | J15: 46196 | K15: Responded
D16: P0155-RA04-SCR-ST-OC-DAR-000003 | F16: 0 | G16: P0155 - K00146 – REH Wadi Yemm - Sea Town Center - Missing data and discrepancy (3) at plot 1025 COL&SLABS | H16: RA04 | I16: 46034 | J16: 46036 | K16: Responded
D17: P0155-RA05-SCR-ST-OC-DAR-000001 | F17: 0 | G17: P0155 - K00146 – REH Wadi Yemm - Sea Town Center - Missing and Conflict data at plot 1026 | H17: RA05 | I17: 46036 | K17: Pending
D18: P0155-RA06-SCR-ST-OC-DAR-000007 | F18: 0 | G18: P0155 - K00146 – REH Wadi Yemm - Sea Town Center - Missing data and conflicts in plot 1024 | H18: RA06 | I18: 46043 | K18: Pending
D19: P0155-RA05-SCR-ST-OC-DAR-000002 | F19: 0 | G19: P0155 - K00146 – REH Wadi Yemm - Sea Town Center - Missing and Conflict data at plot 1026 | H19: RA05 | I19: 46050 | J19: 46106 | K19: Responded
D20: P0155-RA03-SCR-ST-OC-DAR-000003 | F20: 0 | G20: P0155 - K00146 – REH Wadi Yemm - Sea Town Center - Missing data at plot 1047 | H20: RA03 | I20: 46056 | J20: 46068 | K20: Responded
D21: P0155-RA03-SCR-ST-OC-DAR-000004 | F21: 0 | G21: P0155 - K00146 – REH Wadi Yemm - Sea Town Center - Missing data at plot 1047 | H21: RA03 | I21: 46058 | J21: 46068 | K21: Responded
D22: P0155-RA01-SCR-ST-OC-DAR-000001 | F22: 0 | G22: P0155 - K00146 – REH Wadi Yemm - Sea Town Center - Excavation Level required for area infront of Plot 1036 | H22: RA01 | I22: 46056 | J22: 46089 | K22: Responded
D23: P0155-RA03-SCR-ST-OC-DAR-000005 | F23: 0 | G23: P0155 - K00146 – REH Wadi Yemm - Sea Town Center - Data Conflict in plot 1047 | H23: RA03 | I23: 46060 | J23: 46068 | K23: Responded
D24: P0155-RA07-SCR-ST-OC-DAR-000001 | F24: 0 | G24: P0155 - K00146 – REH Wadi Yemm - Sea Town Center - Discrepancy and missing data at Drawings supper plot 01 | H24: RA07 | I24: 46060 | J24: 46072 | K24: Responded
D25: P0155-RA07-SCR-ST-OC-DAR-000002 | F25: 0 | G25: P0155 - K00146 – REH Wadi Yemm - Sea Town Center - Horizontal protection layer and missing axis at supper plot 01 | H25: RA07 | I25: 46063 | J25: 46085 | K25: Responded
D26: P0155-RA04-SCR-ST-OC-DAR-000004 | F26: 0 | G26: P0155 - K00146 – REH Wadi Yemm - Sea Town Center - Missing Structure and Archecture details for stairs at plot 1025 | H26: RA04 | I26: 46034 | J26: 46086 | K26: Responded
D27: P0155-RA00-SCR-BM-OC-DAR-000001 | F27: 0 | G27: P0155 - K00146 – REH Wadi Yemm - Sea Town Center - Approval to use Revit 2026 | H27: RA00 | I27: 46067 | J27: 46080 | K27: Responded
D28: P0155-RA10-SCR-ST-OC-DAR-000001 | F28: 0 | G28: P0155 - K00146 – REH Wadi Yemm - Sea Town Center - Levls PC &RC at plot 1021 | H28: RA10 | I28: 46070 | J28: 46075 | K28: Responded
D29: P0155-RA07-SCR-ST-OC-DAR-000003 | F29: 0 | G29: P0155 - K00146 – REH Wadi Yemm - Sea Town Center - Super Plot 01 – Discrepancies and Missing Data | H29: RA07 | I29: 46070 | J29: 46098 | K29: Responded
D30: P0155-RA09-SCR-ST-OC-DAR-000001 | F30: 0 | G30: P0155 - K00146 – REH Wadi Yemm - Sea Town Center - Conflict Data in Plot 1044 | H30: RA09 | I30: 46070 | J30: 46091 | K30: Responded
... D35: P0155-RA10-SCR-ST-OC-DAR-000003 | F35: 0 | G35: P0155 - K00146 – REH Wadi Yemm - Sea Town Center - Missing Data in Plot 1021 | H35: RA10 | I35: 46072 | J35: 46085 | K35: Responded
D36: P0155-RA04-SCR-ST-OC-DAR-000005 | F36: 0 | G36: P0155 - K00146 – REH Wadi Yemm - Sea Town Center - Missing Column at plot 1036 part 04 | H36: 1036 | I36: 46034 | J36: 46083 | K36: Responded
D37: P0155-RA02-SCR-ST-OC-DAR-000003 | F37: 0 | G37: P0155 - K00146 – REH Wadi Yemm - Sea Town Center - Missing Retaining Walls details & cores conflicts – Plot 1028 | H37: RA02 | I37: 46074 | J37: 46079 | K37: Responded
D38: P0155-RA10-SCR-ST-OC-DAR-000004 | F38: 0 | G38: P0155 - K00146 – REH Wadi Yemm - Sea Town Center - Missing Data in Plot 1021 | H38: RA10 | I38: 46075 | J38: 46085 | K38: Responded
D39: P0155-RA04-SCR-ST-OC-DAR-000006 | F39: 0 | G39: P0155 - K00146 – REH Wadi Yemm - Sea Town Center - Discrepency in additional reinforcement diameter of Retaining wall at plot 1036 part 02 | H39: 1036 | I39: 46075 | J39: 46086 | K39: Responded
D40: P0155-RA06-SCR-ST-OC-DAR-000008 | F40: 0 | G40: P0155 - K00146 – REH Wadi Yemm - Sea Town Center - IFC Clarification at plot 1025 | H40: 1025 | I40: 46077 | J40: 46085 | K40: Responded
D41: P0155-RA07-SCR-ST-OC-DAR-000004 | F41: 0 | G41: P0155 - K00146 – REH Wadi Yemm - Sea Town Cente Super Plot 01 – Discrepancies and Missing Data | H41: RA07 | I41: 46078 | J41: 46087 | K41: Responded
D42: P0155-RA07-SCR-ST-OC-DAR-000005 | F42: 0 | G42: P0155 - K00146 – REH Wadi Yemm - Sea Town Cente conflict at B1 slab plot 1025 | H42: 1025 | I42: 46078 | J42: 46084 | K42: Responded
D43: REH-MD01-MDU-ST-OC-DAR-1047-SCR-000001 | F43: 0 | G43: REH-MD01 - Wadi Yemm - Sea Town Discrepancies in beams & toilet FFL for Plot 1047 | H43: 1047 | I43: 46079 | J43: 46085 | K43: Responded
D44: REH-MD01-MDU-ST-OC-DAR-1029-SCR-000001 | F44: 00 | G44: REH-MD01 - Wadi Yemm - Sea Town Super Plot 01 – Discrepancies and Missing Data | H44: 1029 | I44: 46081 | J44: 46098 | K44: Responded
...

Sheet AR
G2: Site Clarification Request ( Architectural )
D4: Ref. | E4: Mail No | F4: Rev. | G4: Subject | H4: Sub-Building | I4: Issue Date | J4: Received Date | K4: Action
D5: REH-MD01-MDU-AR-OC-Hil-1036-SCR-000001 | E5: REH-MD01-AR-OC-Hil-1036-SCR-01 | F5: 00 | G5: REH-MDU- Wadi Yemm - Provide us the final IFC architectural drawings for the ground floor of Plot-1036 | H5: 1036 | I5: 46152 | J5: 46154 | K5: Responded
D6: REH-MD01-MDU-AR-OC-Hil-1036-SCR-000002 | E6: OC-SCR-000034 | F6: 00 | G6: REH-MDU- Wadi Yemm - Plot-1036 Doors schedule | H6: 1036 | I6: 46155 | J6: 46174 | K6: Responded
D7: REH-MD01-MDU-AR-OC-Hil-1036-SCR-000003 | E7: OC-SCR-000051 | F7: 00 | G7: REH-MDU- Wadi Yemm - Plot-1036 Ramps' slopes | H7: 1036 | I7: 46159 | J7: 46174 | K7: Responded
D8: REH-MD01-MDU-AR-OC-Hil-1034-SCR-000001 | E8: OC-SCR-000097 | F8: 00 | G8: REH-MDU- Wadi Yemm - PLOT-1034 Missing Columns | H8: 1034 | I8: 46166 | J8: 46174 | K8: Responded
D9: REH-MD01-MDU-AR-OC-Hil-1030-SCR-000001 | E9: OC-SCR-000119 | F9: 00 | G9: REH-MDU- Wadi Yemm - PLOT-1030 Pavement & Stairs finishes | H9: 1030 | I9: 46175 | J9: 46183 | K9: Responded
D10: REH-MD01-MDU-AR-OC-Hil-1029-SCR-000001 | E10: OC-SCR-000216 | F10: 00 | G10: REH-MDU- Wadi Yemm - PLOT-1034 Missing plan | H10: 1029 | I10: 46187 | J10: 46190 | K10: Responded
D11: REH-MD01-MDU-AR-OC-Hil-1036-SCR-000004 | E11: OC-SCR-000312 | F11: 00 | G11: REH-MDU- Wadi Yemm - Plot-1036 Slab openings conflict | H11: 1036 | I11: 46198 | J11: 46204 | K11: Responded
D12: REH-MD01-MDU-AR-OC-Hil-1036-SCR-000005 | E12: OC-SCR-000317 | F12: 00 | G12: REH-MDU- Wadi Yemm - Plot-1036 Stairs AR-ST Conflict | H12: 1036 | I12: 46198 | J12: 46204 | K12: Responded
D13: REH-MD01-MDU-AR-OC-Hil-1025-SCR-000001 | E13: OC-SCR-000318 | F13: 00 | G13: REH-MDU- Wadi Yemm - Conflict Door Opening Dimensions and Door Schedule Conflicts for Plot 1025 | H13: 1025 | I13: 46198 | J13: 46204 | K13: Responded
D14: REH-MD01-MDU-AR-OC-Hil-1031-SCR-000001 | E14: OC-SCR-000345 | F14: 00 | G14: REH-MDU- Wadi Yemm - SPLOT 02-1032-B1- Pavement & Stairs finishes | H14: 1031 | I14: 46203 | J14: 46218 | K14: Responded
D15: REH-MD01-MDU-AR-OC-Hil-1024-SCR-000001 | E15: OC-SCR-000362 | F15: 00 | G15: REH-MDU- Wadi Yemm - Clarification on Stairs Sections details -1024 Stair 5 | H15: 1024 | I15: 46204 | J15: 46210 | K15: Responded
D16: REH-MD01-MDU-AR-OC-Hil-1031-SCR-000002 | E16: OC-SCR-000364 | F16: 00 | G16: REH-MDU- Wadi Yemm - Request for Missing Architectural and Landscape Drawings– Super Plot 2 | H16: 1031 | I16: 46204 | J16: 46208 | K16: Responded
... D41: REH-MD01-MDU-AR-OC-Hil-1027-SCR-000004 | E41: OC-SCR-001091 | F41: 00 | G41: REH-MDU- Wadi Yemm - Fortaleza (Plot 1027) –Acoustic and Fire Rating Clarification | H41: 1027 | I41: 46273 | J41: 46280 | K41: Responded
D42: REH-MD01-MDU-AR-OC-Hil-1022-SCR-000003 | E42: OC-SCR-001124 | F42: 00 | G42: REH-MDU- Wadi Yemm - SP06 – Q3 1046 – Planters sizes and locations around the family pool | H42: 1022 | I42: 46275 | K42: Pending
D43: REH-MD01-MDU-AR-OC-Hil-1031-SCR-000004 | E43: OC-SCR-001135 | F43: 00 | G43: REH-MDU- Wadi Yemm - Architectural Files Discrepancies -1031 lower ground plan- SP02 | H43: 1031 | I43: 46278 | K43: Pending
D44: REH-MD01-MDU-AR-OC-Hil-1022-SCR-000004 | E44: OC-SCR-001185 | F44: 00 | G44: REH-MDU- Wadi Yemm - SP06 - PLOT 1045&1046 - PLANTER WALLS CLARIFICATIONS | H44: 1022 | I44: 46281 | J44: 46301 | K44: Responded
D45: REH-MD01-MDU-AR-OC-Hil-XXXX-SCR-000002 | E45: OC-SCR-001191 | F45: 00 | G45: REH-MDU- Wadi Yemm - Cement hollow blocks in basement floors | H45: XXXX | I45: 46281 | K45: Pending
D46: REH-MD01-MDU-ID-OC-Hil-XXXX-SCR-000001 | E46: OC-SCR-001206 | F46: 00 | G46: REH-MDU- Wadi Yemm - DISCREPANCIES BETWEEN ID PLAN AND ID FINISH SCHEDULE AT RESIDENTIAL PLOTS TYPE (Q2) | H46: XXXX | I46: 46282 | J46: 46296 | K46: Responded
D47: REH-MD01-MDU-AR-OC-Hil-1022-SCR-000005 | E47: OC-SCR-001228 | F47: 00 | G47: REH-MDU- Wadi Yemm - SP06 - PLOT 1045 - Part 16 Planter walls clarifications | H47: 1022 | I47: 46284 | J47: 46292 | K47: Responded
D48: REH-MD01-MDU-AR-OC-Hil-1022-SCR-000006 | E48: OC-SCR-001249 | F48: 00 | G48: REH-MDU- Wadi Yemm - SP06 - Plot 1018 - Stairs Clarifications | H48: 1022 | I48: 46285 | J48: 46302 | K48: Responded
D49: REH-MD01-MDU-AR-OC-Hil-1031-SCR-000005 | E49: OC-SCR-001256 | F49: 00 | G49: REH-MDU- Wadi Yemm - Clarification Required for Stair No. 6 door opening -1032 - SP02 | H49: 1031 | I49: 46285 | K49: Pending
D50: REH-MD01-MDU-AR-OC-Hil-1022-SCR-000007 | E50: OC-SCR-001267 | F50: 00 | G50: REH-MDU- Wadi Yemm - Clarifications at SP6-plot 1018 | H50: 1022 | I50: 46286 | J50: 46302 | K50: Responded
D51: REH-MD01-MDU-AR-OC-Hil-1025-SCR-000007 | E51: OC-SCR-001293 | F51: 00 | G51: REH-MDU- Wadi Yemm - Fourth Floor Structural & Architectural Coordination Clarifications | H51: 1025 | I51: 46287 | J51: 46293 | K51: Responded
D52: REH-MD01-MDU-ID-OC-Hil-XXXX-SCR-000002 | E52: OC-SCR-001297 | F52: 0 | G52: REH-MDU- Wadi Yemm - DISCREPANCIES BETWEEN ID PLAN AND ID FINISH SCHEDULE AT RESIDENTIAL PLOTS TYPE (Q3) | H52: XXXX | I52: 46288 | J52: 46294 | K52: Responded
D53: REH-MD01-MDU-ID-OC-Hil-XXXX-SCR-000003 | E53: OC-SCR-001296 | F53: 0 | G53: REH-MDU- Wadi Yemm - DISCREPANCIES BETWEEN ID PLAN AND ID FINISH SCHEDULE AT RESIDENTIAL PLOTS TYPE (Q4) | H53: XXXX | I53: 46288 | J53: 46294 | K53: Responded
D54: REH-MD01-MDU-AR-OC-Hil-1024-SCR-000006 | E54: OC-SCR-001340 | F54: 0 | G54: REH-MDU- Wadi Yemm - Clarification on internal stairs Naming - Plot 1024 | H54: 1024 | I54: 46292 | K54: Pending
D55: REH-MD01-MDU-AR-OC-Hil-1024-SCR-000007 | E55: OC-SCR-001360 | F55: 0 | G55: REH-MDU- Wadi Yemm - Clarification on Stair 07 missing data -plot 1024 | H55: 1024 | I55: 46295 | J55: 46302 | K55: Responded
D56: REH-MD01-MDU-AR-OC-Hil-XXXX-SCR-000003 | E56: OC-SCR-001370 | F56: 0 | G56: REH-MDU- Wadi Yemm - Block work details (100 mm, 150 mm & 400 mm) | H56: XXXX | I56: 46296 | J56: 46296 | K56: Responded
D57: REH-MD01-MDU-AR-OC-Hil-XXXX-SCR-000004 | E57: OC-SCR-001374 | F57: 0 | G57: REH-MD01-MDU-AR-OC-Hil-XXXX-SCR-000004 - Clarification of Door Structural Opening Dimensions | H57: XXXX | I57: 46296 | J57: 46300 | K57: Responded
D58: REH-MD01-MDU-AR-OC-Hil-1022-SCR-000008 | E58: OC-SCR-001423 | F58: 0 | G58: REH-MD01-MDU-AR-OC-Hil-1022-SCR-000008- Discrepancies Between Arch. IFC and the Wall Types, Acoustic & Life Safety Requirements – First Floor | H58: 1022 | I58: 46300 | K58: Pending
D59: REH-MD01-MDU-AR-OC-Hil-1047-SCR-000001 | E59: OC-SCR-001417 | F59: 0 | G59: REH-MD01-MDU-AR-OC-Hil-1047-SCR-000001 - Missing Door - Basement 01 & Wall Extension Typical Floors | H59: 1047 | I59: 46300 | J59: 46300 | K59: Responded
D60: REH-MD01-MDU-AR-OC-Hil-XXXX-SCR-000005 | E60: OC-SCR-001438 | F60: 0 | G60: REH-MD01-MDU-AR-OC-Hil-XXXX-SCR-000005 - Plaster Thickness | H60: XXXX | I60: 46301 | J60: 46302 | K60: Responded
D61: REH-MD01-MDU-AR-OC-Hil-XXXX-SCR-000006 | E61: OC-SCR-001490 | F61: 0 | G61: REH-MD01-MDU-AR-OC-Hil-XXXX-SCR-000006-00 - Following ECG specs & typical details | H61: XXXX | I61: 46306 | K61: Pending
D62: REH-MD01-MDU-AR-OC-Hil-XXXX-SCR-000007 | E62: OC-SCR-001491 | F62: 0 | G62: REH-MD01-MDU-AR-OC-Hil-XXXX-SCR-000007-00 - RC stiffening for blockwork | H62: XXXX | I62: 46306 | K62: Pending
D63: REH-MD01-MDU-AR-OC-Hil-XXXX-SCR-000008 | E63: OC-SCR-001492 | F63: 0 | G63: REH-MD01-MDU-AR-OC-Hil-XXXX-SCR-000008-00 - DPC CAVITY TRAY AND WEEPHOLES CANCELLATION | H63: XXXX | I63: 46306 | K63: Pending
D64: EH-MD01-MDU-AR-OC-Hil-1060-SCR-000001 | E64: OC-SCR-001497 | F64: 0 | G64: REH-MD01-MDU-AR-OC-Hil-1060-SCR-000001 - Coordination Issues Related to Sump Pit Access Requirements | H64: 1060 | I64: 46306 | K64: Pending
D65: REH-MD01-MDU-AR-OC-Hil-1021-SCR-000005 | E65: OC-SCR-001512 | F65: 0 | G65: REH-MD01-MDU-AR-OC-Hil-1021-SCR-000005 - Design Discrepancy Between Architectural and Structural IFC – Waste Lift Core Wall (Basement 02) | H65: 1021 | I65: 46306 | K65: Pending
D66: REH-MD01-MDU-AR-OC-Hil-1021-SCR-000004 | E66: OC-SCR-001511 | F66: 0 | G66: REH-MD01-MDU-AR-OC-Hil-1021-SCR-000004 - Design Discrepancies and Missing Information regarding FLS & Acoustic documents | H66: 1021 | I66: 46306 | K66: Pending
...

Sheet EL
G2: Site Clarification Request ( Electrical )
D4: Ref. | E4: Mail No | F4: Rev. | G4: Subject | H4: Sub-Building | I4: Issue Date | J4: Received Date | K4: Action
D5: P0155-RA04-SCR-EL-OC-DAR-000001 | E5: Darr-GNC-000383 | F5: 0 | G5: P0155 - K00146 – REH Wadi Yemm - Sea Town Center - Missing Data for Earthing System at plot 1025 | H5: RA04 | I5: 46016 | J5: 46198 | K5: Responded
D6: P0155-RA06-SCR-EL-OC-DAR-000001 | E6: Darr-GNC-000384 | F6: 0 | G6: P0155 - K00146 – REH Wadi Yemm - Sea Town Center - Missing Data for Earthing System at plot 1024 | H6: RA06 | I6: 46016 | J6: 46099 | K6: Responded
D7: P0155-RA06-SCR-MV-OC-DAR-000001 | E7: Darr-GNC-000393 | F7: 0 | G7: P0155 - K00146 – REH Wadi Yemm - Sea Town Center - MV Routing at plot 1024 | H7: RA06 | I7: 46026 | K7: Pending
D8: P0155-RA06-SCR-EL-OC-DAR-000002 | E8: Darr-GNC-000384 | F8: 0 | G8: P0155 - K00146 – REH Wadi Yemm - Sea Town Center - Missing Data for Earthing System at plot 1024 | H8: RA06 | I8: 46056 | J8: 46068 | K8: Responded
D9: P0155-RA00-SCR-EL-OC-DAR-000001 | E9: Darr-GNC-000364 | F9: 0 | G9: P0155 - K00146 – REH Wadi Yemm - Sea Town Center - Embedded MEP works at Wadi Yemm | H9: RA00 | I9: 46067 | J9: 46085 | K9: Responded
D10: P0155-RA00-SCR-EL-OC-DAR-000002 | F10: 0 | G10: P0155 - K00146 – REH Wadi Yemm - Sea Town Center - Lightning down conductor general details at Wadi Yemm | H10: RA00 | I10: 46070 | J10: 46085 | K10: Responded
D11: REH-MD01-MDU-EL-OC-DAR-XXXX-SCR-000001 | F11: 1 | G11: REH-MD01-MDU -Wadi Yemm - Sea Town Center - Lightning down conductor general details at Wadi Yemm | H11: RA00 | I11: 46082 | J11: 46087 | K11: Responded
D12: REH-MD01-MDU-EL-OC-DAR-1024-SCR-000001 | F12: 0 | G12: REH-MD01-MDU -Wadi Yemm - Sea Town Center - Request for Cable Cellar Details at RA06 - Plot 1024 | H12: 1024 | I12: 46128 | J12: 46141 | K12: Responded
D13: REH-MD01-MDU-EL-OC-DAR-1024-SCR-000002 | F13: 0 | G13: REH-MD01-MDU -Wadi Yemm - Sea Town Center - Conflict in Power Shaft Location & Request for Cable Data for Slab Openings at RA06 - Plot 1024 | H13: 1024 | I13: 46128 | J13: 46142 | K13: Responded
D14: REH-MD01-MDU-EL-OC-DAR-1026-SCR-000001 | F14: 0 | G14: REH-MD01-MDU -Wadi Yemm - Sea Town Center - Telecome Shaft opening of Basement slap at RA05 - Plot 1026 | H14: 1026 | I14: 46130 | J14: 46133 | K14: Responded
D15: REH-MD01-MDU-EL-OC-DAR-1024-SCR-000003 | F15: 0 | G15: REH-MD01-MDU -Wadi Yemm - Sea Town Center - Clarification of Electrical Riser Size (LV & ELV) - RA06-1024 | H15: 1024 | I15: 46134 | J15: 46142 | K15: Responded
D16: REH-MD01-MDU-EL-OC-DAR-1025-SCR-000001 | F16: 0 | G16: REH-MD01-MDU -Wadi Yemm - Sea Town Center - Clarification of Electrical Riser Size (LV & ELV) - RA04-1025 | H16: 1025 | I16: 46134 | J16: 46142 | K16: Responded
D17: REH-MD01-MDU-EL-OC-DAR-1024-SCR-000004 | E17: REH-MD01-EL-OC-DAR-1024-SCR-04 | F17: 0 | G17: REH-MD01-MDU -Wadi Yemm - Sea Town Center - Clarify the Routing For Low Voltage cables between grid 519, 523 at basement- RA06 - Plot 1024 | H17: 1024 | I17: 46140 | J17: 46142 | K17: Responded
D18: REH-MD01-MDU-EL-OC-DAR-1024-SCR-000005 | E18: REH-MD01-EL-OC-DAR-1024-SCR-05 | F18: 0 | G18: REH-MD01-MDU -Wadi Yemm - Sea Town Center - Shaft Opening for Low Current Cables at Entrance Facility room at basement- RA06 - Plot 1024 | H18: 1024 | I18: 46140 | J18: 46145 | K18: Responded
D19: REH-MD01-MDU-EL-OC-Hil-1024-SCR-000001 | F19: 0 | G19: REH-MD01-MDU -Wadi Yemm - Sea Town Center - Clarification of Shaft for Retails in RA06 | H19: 1024 | I19: 46148 | J19: 46161 | K19: Responded
D20: REH-MD01-MDU-EL-OC-Hil-1024-SCR-000002 | E20: REH-MD01-EL-OC-Hil-1024-SCR-02 | F20: 0 | G20: REH-MD01-MDU -Wadi Yemm - Sea Town Center - Clash between Electrical Trench and Mechanical Shaft in RMU Room Plot 1024 | H20: 1024 | I20: 46148 | J20: 46159 | K20: Responded
D21: REH-MD01-MDU-EL-OC-Hil-1028-SCR-000001 | E21: REH-MD01-EL-OC-Hil-1028-SCR-01 | F21: 0 | G21: REH-MD01-MDU -Wadi Yemm - Sea Town Center - LV SLD vs Cable Routing Drawings Conflict at (RA02 - Plot 1028). | H21: 1028 | I21: 46148 | J21: 46154 | K21: Responded
D22: REH-MD01-MDU-EL-OC-Hil-1028-SCR-000002 | E22: REH-MD01-EL-OC-Hil-1028-SCR-02 | F22: 0 | G22: REH-MD01-MDU -Wadi Yemm - Sea Town Center - Conflict between the Electrical down conductor Ground Floor - Plot 1028 | H22: 1028 | I22: 46148 | J22: 46155 | K22: Responded
D23: REH-MD01-MDU-EL-OC-Hil-1036-SCR-000001 | E23: REH-MD01-EL-OC-Hil-1036-SCR-01 | F23: 0 | G23: REH-MD01-MDU -Wadi Yemm - Sea Town Center - LV SLD vs Cable Routing Drawings Conflict at (RA01 - Plot 1036). | H23: 1036 | I23: 46152 | J23: 46153 | K23: Responded
D24: REH-MD01-MDU-EL-OC-Hil-1030-SCR-000001 | E24: REH-MD01-EL-OC-Hil-1030-SCR-01 | F24: 0 | G24: REH-MD01-MDU -Wadi Yemm - Sea Town Center - RMU Room Location at (RA07 - Plot 1030). | H24: 1030 | I24: 46152 | J24: 46156 | K24: Responded
D25: REH-MD01-MDU-EL-OC-Hil-1036-SCR-000002 | E25: REH-MD01-EL-OC-Hil-1036-SCR-02 | F25: 0 | G25: REH-MD01-MDU -Wadi Yemm - Sea Town Center -Location of panel boards at business lounge and kids room at Building (RA01 - Plot 1036). | H25: 1036 | I25: 46153 | J25: 46155 | K25: Responded
D26: REH-MD01-MDU-EL-OC-Hil-XXXX-SCR-000001 | E26: REH-MD01-EL-OC-Hil-XXXX-SCR-01 | F26: 0 | G26: REH-MD01-MDU -Wadi Yemm - Lighting Control System Conflict (Shaker) | H26: XXXX | I26: 46154 | J26: 46156 | K26: Responded
D27: REH-MD01-MDU-EL-OC-Hil-XXXX-SCR-000002 | E27: REH-MD01-EL-OC-Hil-XXXX-SCR-02 | F27: 0 | G27: REH-MD01-MDU -Wadi Yemm - Clarification for Electrical Legend and Lighting Control System (ECG) | H27: XXXX | I27: 46154 | J27: 46174 | K27: Responded
D28: REH-MD01-MDU-EL-OC-Hil-1047-SCR-000001 | E28: OC-SCR-000058 | F28: 0 | G28: REH-MD01-MDU -Wadi Yemm - Conflict between SLD and plans and missing feeding power for retail (RA03 - Plot 1047). | H28: 1047 | I28: 46161 | J28: 46176 | K28: Responded
D29: REH-MD01-MDU-EL-OC-Hil-1025-SCR-000001 | E29: OC-SCR-000068 | F29: 0 | G29: REH-MD01-MDU -Wadi Yemm - VIA Occupancy Sensor Connection Clarification- Plot 1025- Ground Floor | H29: 1025 | I29: 46162 | J29: 46175 | K29: Responded
D30: REH-MD01-MDU-EL-OC-Hil-1025-SCR-000002 | E30: OC-SCR-000069 | F30: 0 | G30: REH-MD01-MDU -Wadi Yemm - Wall Mounted Lighting Fixture Host Issue - Plot 1025 -Ground Floor. | H30: 1025 | I30: 46162 | J30: 46176 | K30: Responded
D31: REH-MD01-MDU-EL-OC-Hil-1025-SCR-000003 | E31: OC-SCR-000070 | F31: 0 | G31: REH-MD01-MDU - Wadi Yemm - Ceiling Speaker Wiring and Riser Diagram Clarification- Plot 1025-Ground Floor | H31: 1025 | I31: 46162 | J31: 46181 | K31: Responded
... D36: REH-MD01-MDU-EL-OC-Hil-1025-SCR-000004 | E36: OC-SCR-000116 | F36: 0 | G36: REH-MD01-MDU -Wadi Yemm - Data outlets on Concrete column - Ground Floor | H36: 1025 | I36: 46175 | J36: 46180 | K36: Responded
D37: REH-MD01-MDU-EL-OC-Hil-1047-SCR-000002 | F37: 0 | G37: REH-MD01-MDU -Wadi Yemm - RMU Room Location of RA03 - Plot 1047 at Basement Level | H37: 1047 | I37: 46182 | J37: 46183 | K37: Responded
D38: REH-MD01-MDU-EL-OC-Hil-XXXX-SCR-000006 | E38: OC-SCR-000184 | F38: 0 | G38: REH-MD01-MDU -Wadi Yemm - Clarification Regarding CS (Conventional Smoke Detector) scope | H38: XXXX | I38: 46183 | J38: 46196 | K38: Responded
D39: REH-MD01-MDU-EL-OC-Hil-XXXX-SCR-000007 | E39: OC-SCR-000207 | F39: 0 | G39: REH-MD01-MDU -Wadi Yemm - Required for Fire Alarm Detection Concept at Apartments | H39: XXXX | I39: 46186 | J39: 46189 | K39: Responded
D40: REH-MD01-MDU-EL-OC-Hil-1032-SCR-000001 | E40: OC-SCR-000212 | F40: 0 | G40: REH-MD01-MDU -Wadi Yemm - RMU Room Location of SP02 - Plot 1032 - Conflict between the columns and trench. | H40: 1032 | I40: 46187 | J40: 46191 | K40: Responded
D41: REH-MD01-MDU-EL-OC-Hil-XXXX-SCR-000008 | E41: OC-SCR-000220 | F41: 0 | G41: REH-MD01-MDU -Wadi Yemm - Discrepancies in Earthing Cable Sizes between Layout and Riser Drawings (Shaker Package) | H41: XXXX | I41: 46188 | J41: 46190 | K41: Responded
D42: REH-MD01-MDU-EL-OC-Hil-XXXX-SCR-000009 | E42: OC-SCR-000225 | F42: 0 | G42: REH-MD01-MDU -Wadi Yemm -Power System Clashes Between Electrical and Interior Design (ELEC & ID) – 100% (DD) Shaker Package – Apartment Layouts – (Q2). | H42: XXXX | I42: 46188 | J42: 46196 | K42: Responded
D43: REH-MD01-MDU-EL-OC-Hil-XXXX-SCR-000010 | E43: OC-SCR-000226 | F43: 0 | G43: REH-MD01-MDU -Wadi Yemm -Power System Clashes Between Electrical and Interior Design (ELEC & ID) – 100% (DD) Shaker Package – Apartment Layouts – (Q3). | H43: XXXX | I43: 46188 | J43: 46199 | K43: Responded
D44: REH-MD01-MDU-EL-OC-Hil-XXXX-SCR-000011 | E44: OC-SCR-000227 | F44: 0 | G44: REH-MD01-MDU -Wadi Yemm -Power System Clashes Between Electrical and Interior Design (ELEC & ID) – 100% (DD) Shaker Package – Apartment Layouts – (Q4). | H44: XXXX | I44: 46188 | J44: 46199 | K44: Responded
D45: REH-MD01-MDU-EL-OC-Hil-XXXX-SCR-000012 | E45: OC-SCR-000232 | F45: 0 | G45: REH-MD01-MDU -Wadi Yemm -Discrepancy Lighting control scenario at Drawings (Shaker Package) | H45: XXXX | I45: 46188 | J45: 46196 | K45: Responded
D46: REH-MD01-MDU-EL-OC-Hil-XXXX-SCR-000013 | E46: OC-SCR-000233 | F46: 0 | G46: REH-MD01-MDU -Wadi Yemm -Conflict in conventional switch locations & types between Shaker 100% DD & Shaker 100% ID (Shaker Package) | H46: XXXX | I46: 46188 | J46: 46196 | K46: Responded
...

Sheet ME
G2: Site Clarification Request ( Mechanical )
D4: Ref. | E4: Mail No | F4: Rev. | G4: Subject | H4: Sub-Building | I4: Issue Date | J4: Received Date | K4: Action
D5: P0155-RA06-SCR-ME-OC-DAR-000001 | F5: 0 | G5: P0155 - K00146 – REH Wadi Yemm - Sea Town Center - MEP Elevators Builder work at plot 1024 | H5: RA06 | I5: 46015 | J5: 46096 | K5: Responded
D6: P0155-RA06-SCR-ME-OC-DAR-000002 | F6: 0 | G6: P0155 - K00146 – REH Wadi Yemm - Sea Town Center - MEP SUMP PIT Builder work at plot 1024 | H6: RA06 | I6: 46015 | J6: 46092 | K6: Responded
D7: P0155-RA06-SCR-ME-OC-DAR-000003 | F7: 0 | G7: P0155 - K00146 – REH Wadi Yemm - Sea Town Center - MEP TANKS Builder work at plot 1024 | H7: RA06 | I7: 46015 | J7: 46096 | K7: Responded
D8: P0155-RA06-SCR-ME-OC-DAR-000004 | F8: 0 | G8: P0155 - K00146 – REH Wadi Yemm - Sea Town Center - MEP Grease Interceptors Builder work at plot 1024 | H8: RA06 | I8: 46015 | J8: 46093 | K8: Responded
D9: P0155-RA04-SCR-ME-OC-DAR-000001 | F9: 0 | G9: P0155 - K00146 – REH Wadi Yemm - Sea Town Center - MEP Elevators Builder work at plot 1025 | H9: RA04 | I9: 46016 | J9: 46099 | K9: Responded
D10: P0155-RA04-SCR-ME-OC-DAR-000002 | F10: 0 | G10: P0155 - K00146 – REH Wadi Yemm - Sea Town Center - MEP SUMP PIT Builder work at plot 1025 | H10: RA04 | I10: 46016 | J10: 46099 | K10: Responded
D11: P0155-RA04-SCR-ME-OC-DAR-000003 | F11: 0 | G11: P0155 - K00146 – REH Wadi Yemm - Sea Town Center - MEP TANKS Builder work at plot 1025 | H11: RA04 | I11: 46016 | J11: 46099 | K11: Responded
D12: P0155-RA04-SCR-ME-OC-DAR-000004 | F12: 0 | G12: P0155 - K00146 – REH Wadi Yemm - Sea Town Center - MEP Grease Interceptors Builder work at plot 1025 | H12: RA04 | I12: 46016 | J12: 46100 | K12: Responded
D13: P0155-RA06-SCR-ME-OC-DAR-000005 | F13: 0 | G13: P0155 - K00146 – REH Wadi Yemm - Sea Town Center - Waste Pipes Slope and Invert Level at Plot 1024 | H13: RA06 | I13: 46023 | J13: 46085 | K13: Responded
D14: P0155-RA06-SCR-ME-OC-DAR-000006 | F14: 0 | G14: P0155 - K00146 – REH Wadi Yemm - Sea Town Center - Mechanical works retaining wall opening at Plot 1024 | H14: RA06 | I14: 46056 | J14: 46068 | K14: Responded
D15: P0155-RA07-SCR-ME-OC-DAR-000001 | F15: 0 | G15: P0155 - K00146 – REH Wadi Yemm - Sea Town Center - Sump Pits conflict at SP1 | H15: RA07 | I15: 46062 | J15: 46072 | K15: Responded
D16: P0155-RA04-SCR-AC-OC-DAR-000001 | F16: 0 | G16: P0155 - K00146 – REH Wadi Yemm - Sea Town Center - AC duct conflict with ramp retaining wall at plot 1025 | H16: RA04 | I16: 46067 | J16: 46085 | K16: Responded
D17: P0155-RA00-SCR-AC-OC-DAR-000001 | F17: 0 | G17: P0155 - K00146 – REH Wadi Yemm - Sea Town Center - Sump Pits conflict at SP1, SP3 and SP4 | H17: RA00 | I17: 46070 | J17: 46086 | K17: Responded
D18: P0155-RA04-SCR-ME-OC-DAR-000005 | F18: 0 | G18: P0155 - K00146 – REH Wadi Yemm - Sea Town Center -PARKING DRAIN ABOVEGROUND and Trench Drain at plote 1025 | H18: RA04 | I18: 46078 | K18: Pending
D19: REH-MD01-MDU-ME-OC-DAR-XXXX-SCR-000001 | F19: 0 | G19: REH-MD01-MDU - Wadi Yemm - Sea Town Center - Tanks and pump rooms mechanical works | H19: RA00 | I19: 46083 | J19: 46092 | K19: Responded
D20: REH-MD01-MDU-ME-OC-DAR-1025-SCR-000001 | F20: 0 | G20: REH-MD01-MDU - Wadi Yemm Combined fire and water tank at plot 1025 | H20: 1025 | I20: 46085 | J20: 46087 | K20: Responded
D21: REH-MD01-MDU-ME-OC-DAR-XXXX-SCR-000002 | F21: 0 | G21: REH-MD01-MDU - Wadi Yemm Tanks and pump rooms mechanical works at SP1, SP2, SP3, SP4 & SP6 | H21: RA00 | I21: 46090 | J21: 46142 | K21: Responded
D22: REH-MD01-MDU-ME-OC-DAR-XXXX-SCR-000003 | F22: 0 | G22: REH-MD01-MDU - Wadi Yemm H/L piping slopes and invert levels at ECG (RA01 : RA06) Plots | H22: RA00 | I22: 46090 | J22: 46096 | K22: Responded
D23: REH-MD01-MDU-ME-OC-DAR-XXXX-SCR-000004 | F23: 0 | G23: REH-MD01-MDU - Wadi Yemm H/L piping slopes and invert levels at SP1, SP2, SP3, SP4 & SP6 | H23: RA00 | I23: 46090 | J23: 46142 | K23: Responded
D24: REH-MD01-MDU-ME-OC-DAR-1047-SCR-000001 | F24: 0 | G24: REH-MD01-MDU - Wadi Yemm Plot 1047 - Arch & Drainage conflict | H24: 1047 | I24: 46093 | J24: 46097 | K24: Responded
D25: REH-MD01-MDU-ME-OC-DAR-XXXX-SCR-000005 | F25: 0 | G25: REH-MD01-MDU - Wadi Yemm -Bathrooms waste drainage at basement 01(proposal) | H25: RA00 | I25: 46128 | J25: 46135 | K25: Responded
D26: REH-MD01-MDU-ME-OC-DAR-XXXX-SCR-000006 | F26: 0 | G26: REH-MD01-MDU - Wadi Yemm -Bathrooms waste drainage at basement 02(proposal) | H26: RA00 | I26: 46128 | J26: 46135 | K26: Responded
D27: REH-MD01-MDU-ME-OC-DAR-XXXX-SCR-000007 | F27: 0 | G27: REH-MD01-MDU - Wadi Yemm - Tanks and pump rooms mechanical works | H27: RA00 | I27: 46131 | J27: 46134 | K27: Responded
D28: REH-MD01-MDU-AC-OC-DAR-1025-SCR-000001 | F28: 0 | G28: REH-MD01-MDU - Wadi Yemm - Clarification on Duct Material (Black Steel vs. Galvanized Steel) | H28: 1025 | I28: 46134 | J28: 46153 | K28: Responded
D29: REH-MD01-MDU-ME-OC-DAR-1024-SCR-000001 | F29: 0 | G29: REH-MD01-MDU - Wadi Yemm - Conflict between drainage pipes and structural caps at plot 1024 | H29: 1024 | I29: 46135 | J29: 46142 | K29: Responded
D30: REH-MD01-MDU-FS-OC-DAR-1036-SCR-000001 | F30: 0 | G30: REH-MD01-MDU - Wadi Yemm - Clarification Fire Hose Cabinet Location & Dimension at Stair Core | H30: 1036 | I30: 46138 | J30: 46142 | K30: Responded
... D32: REH-MD01-MDU-ME-OC-DAR-1024-SCR-000003 | F32: 0 | G32: REH-MD01-MDU - Wadi Yemm - Insufficient shaft opening for drainage pipes at plot 1024 | H32: 1024 | I32: 46138 | J32: 46140 | K32: Responded
D33: REH-MD01-MDU-ME-OC-DAR-1025-SCR-000002 | E33: REH-MD01-ME-OC-DAR-1025-SCR-02 | F33: 0 | G33: REH-MD01-MDU - Wadi Yemm - Insufficient cavity space behind plumbing fixtures for soil pipes at plot 1025 | H33: 1025 | I33: 46138 | J33: 46141 | K33: Responded
D34: REH-MD01-MDU-FS-OC-DAR-1028-SCR-000001 | E34: REH-MD01-FS-OC-DAR-1028-SCR-01 | F34: 0 | G34: REH-MD01-MDU - Wadi Yemm - Clarification on Domestic Pump Arrangement for plot 1028 (RA02) | H34: 1028 | I34: 46139 | J34: 46142 | K34: Responded
D35: REH-MD01-MDU-ME-OC-Hil-1036-SCR-000001 | E35: REH-MD01-ME-OC-Hil-1036-SCR-01 | F35: 0 | G35: REH-MD01-MDU - Wadi Yemm - Remark on Suction Line Arrangement, Tank Internal Walls, and Missing Drain – Fire Tank, Plot 1036 | H35: 1036 | I35: 46145 | J35: 46148 | K35: Responded
D36: REH-MD01-MDU-ME-OC-Hil-1024-SCR-000001 | E36: REH-MD01-ME-OC-Hil-1024-SCR-01 | F36: 0 | G36: REH-MD01-MDU - Wadi Yemm - Openings in Column Caps | H36: 1024 | I36: 46146 | J36: 46154 | K36: Responded
D37: REH-MD01-MDU-ME-OC-Hil-1024-SCR-000002 | E37: REH-MD01-ME-OC-Hil-1024-SCR-02 | F37: 0 | G37: REH-MD01-MDU - Wadi Yemm - Clarification of Shaft for Retails in RA06 | H37: 1024 | I37: 46146 | J37: 46147 | K37: Responded
D38: REH-MD01-MDU-ME-OC-Hil-1025-SCR-000001 | E38: REH-MD01-ME-OC-Hil-1025-SCR-01 | F38: 0 | G38: REH-MD01-MDU - Wadi Yemm - Clarification on irrigation water pipe Routing at Hardscape and Swimming pool area Plot RA04(1025) Ground Floor | H38: 1025 | I38: 46146 | J38: 46154 | K38: Responded
D39: REH-MD01-MDU-ME-OC-Hil-1025-SCR-000002 | E39: REH-MD01-ME-OC-Hil-1025-SCR-02 | F39: 0 | G39: REH-MD01-MDU - Wadi Yemm - Clarification on Trench Darin Pipe Plot RA04(1025) Ground Floor | H39: 1025 | I39: 46146 | J39: 46149 | K39: Responded
D40: REH-MD01-MDU-ME-OC-Hil-1028-SCR-000001 | E40: REH-MD01-ME-OC-Hil-1028-SCR-01 | F40: 0 | G40: REH-MD01-MDU - Wadi Yemm - Architectural shafts, mechanical and drainage Works Clash | H40: 1028 | I40: 46146 | J40: 46149 | K40: Responded
D41: REH-MD01-MDU-ME-OC-Hil-1025-SCR-000003 | E41: REH-MD01-ME-OC-Hil-1025-SCR-03 | F41: 0 | G41: REH-MD01-MDU - Wadi Yemm - Changes in Openings Due to Coordination Conflicts | H41: 1025 | I41: 46147 | J41: 46154 | K41: Responded
D42: REH-MD01-MDU-ME-OC-Hil-XXXX-SCR-000001 | E42: REH-MD01-ME-OC-Hil-xxxx-SCR-01 | F42: 0 | G42: REH-MD01-MDU - Wadi Yemm - Floor Drain Openings | H42: XXXX | I42: 46147 | J42: 46147 | K42: Responded
D43: REH-MD01-MDU-ME-OC-Hil-1030-SCR-000001 | E43: REH-MD01-ME-OC-Hil-1030-SCR-01 | F43: 00 | G43: REH-MD01-MDU - Wadi Yemm Request for Confirmation of Drainage Levels Relative to Road Level – Plot 1030 | H43: 1030 | I43: 46153 | J43: 46174 | K43: Responded
...

Sheet Telecom
D2: Site Clarification Request ( Telecommunication )
A4: Ref. | B4: Mail No | C4: Rev. | D4: Subject | E4: Sub-Building | F4: Issue Date | G4: Received Date | H4: Action
A5: REH-MD01-MDU-TE-OC-Hil-XXXX-SCR-000032 | B5: OC-SCR-000790 | C5: 0 | D5: REH-MD01-MDU -Wadi Yemm - ONT/ONU Conduit For Incoming Cable Conflication | E5: XXXX | F5: 46247 | G5: 46251 | H5: Responded
A6: REH-MD01-MDU-TE-OC-Hil-XXXX-SCR-000033 | B6: OC-SCR-000808 | C6: 0 | D6: REH-MD01-MDU -Wadi Yemm - Clarification Required for Disabled Toilet Alarm system (System Configuration - Control Panel Capacity) | E6: XXXX | F6: 46247 | G6: 46251 | H6: Responded
A7: REH-MD01-MDU-TE-OC-Hil-XXXX-SCR-000034 | B7: OC-SCR-000809 | C7: 0 | D7: REH-MD01-MDU -Wadi Yemm - Clarification Required for Disabled Toilet Alarm system ( Spare Parts - UL Approval - Emergency Power Supply ) | E7: XXXX | F7: 46247 | G7: 46253 | H7: Responded
A8: REH-MD01-MDU-TE-OC-Hil-1044-SCR-000005 | B8: OC-SCR-000810 | C8: 0 | D8: REH-MD01-MDU -Wadi Yemm - AV SYSTEM OF KIDS ROOM - GROUND FLOOR - 1044 | E8: 1044 | F8: 46247 | G8: 46253 | H8: Responded
A9: REH-MD01-MDU-TE-OC-Hil-1018-SCR-000001 | B9: OC-SCR-000820 | C9: 0 | D9: REH-MD01-MDU -Wadi Yemm - Missing Data Outlet for LCP at Plot 1018 | E9: 1018 | F9: 46251 | G9: 46257 | H9: Responded
A10: REH-MD01-MDU-TE-OC-Hil-1018-SCR-000002 | B10: OC-SCR-000831 | C10: 0 | D10: REH-MD01-MDU -Wadi Yemm - Missing Fiber Optic Rack for ONU at Ground Floor FTR Room in Plot 1018 | E10: 1018 | F10: 46251 | G10: 46257 | H10: Responded
A11: REH-MD01-MDU-TE-OC-Hil-1022-SCR-000004 | B11: OC-SCR-000832 | C11: 0 | D11: REH-MD01-MDU -Wadi Yemm - Access Control Devices Installation at Entrance Gate -Plot 1022 | E11: 1022 | F11: 46251 | G11: 46258 | H11: Responded
A12: REH-MD01-MDU-TE-OC-Hil-XXXX-SCR-000038 | B12: OC-SCR-000842 | C12: 0 | D12: REH-MD01-MDU -Wadi Yemm - DAS Room Minimum Space Requirement – Clarification Request | E12: XXXX | F12: 46252 | G12: 46258 | H12: Responded
A13: REH-MD01-MDU-TE-OC-Hil-1018-SCR-000005 | B13: OC-SCR-000847 | C13: 0 | D13: REH-MD01-MDU -Wadi Yemm - LOCATION OF IT RACK IN MULTIPURPOSE ROOM - Plot 1018 | E13: 1018 | F13: 46252 | G13: 46258 | H13: Responded
A14: REH-MD01-MDU-TE-OC-Hil-1045-SCR-000008 | B14: OC-SCR-000877 | C14: 0 | D14: REH-MD01-MDU -Wadi Yemm - AV System – Speaker Quantity & AV Wall Outlet Coordination - 1045 | E14: 1045 | F14: 46253 | G14: 46259 | H14: Responded
A15: REH-MD01-MDU-TE-OC-Hil-XXXX-SCR-000041 | B15: OC-SCR-000885 | C15: 0 | D15: REH-MD01-MDU -Wadi Yemm - Different Design Details in LC SLDs – Clarification Request | E15: XXXX | F15: 46254 | G15: 46260 | H15: Responded
A16: REH-MD01-MDU-TE-OC-Hil-1026-SCR-000014 | B16: OC-SCR-000990 | C16: 0 | D16: REH-MD01-MDU -Wadi Yemm - Missing Door Controller panels and Data Points & Level Discrepancy in IFC/PDF drawings - ground floor plot (1026) | E16: 1026 | F16: 46265 | G16: 46266 | H16: Responded
... A19: REH-MD01-MDU-TE-OC-Hil-XXXX-SCR-000059 | B19: OC-SCR-001154 | C19: 0 | D19: REH-MD01-MDU -Wadi Yemm - Clarification for Telecommunication – External Interface (HILL/MODON) | E19: XXXX | F19: 46279 | G19: 46286 | H19: Responded
A20: REH-MD01-MDU-TE-OC-Hil-1018-SCR-000022 | B20: OC-SCR-001163 | C20: 0 | D20: REH-MD01-MDU -Wadi Yemm - RACK AND SLAB OPENING Clarification - PLOT 1018-FIRST BASEMENT&GROUND FLOOR | E20: 1018 | F20: 46279 | G20: 46282 | H20: Responded
A21: REH-MD01-MDU-TE-OC-Hil-1023-SCR-000001 | B21: OC-SCR-001177 | C21: 0 | D21: REH-MD01-MDU -Wadi Yemm - CHANGE THE SHAFT LOCATION FOR LIGHT CURRENT | E21: 1023 | F21: 46280 | G21: 46294 | H21: Responded
A22: REH-MD01-MDU-TE-OC-Hil-XXXX-SCR-000066 | B22: OC-SCR-001275 | C22: 0 | D22: REH-MD01-MDU - Wadi Yemm - Clarification of Our Scope Regarding Low Current Systems Components (ECG/Shaker) | E22: XXXX | F22: 46286 | H22: Pending
A23: REH-MD01-MDU-TE-OC-Hil-1031-SCR-000005 | B23: OC-SCR-001277 | C23: 00 | D23: REH-MD01-MDU - Wadi Yemm - Clarification Regarding AMENITIES Telecom Single Line Diagram System - SP02 | E23: 1031 | F23: 46287 | G23: 46289 | H23: Responded
A24: REH-MD01-MDU-TE-OC-Hil-1046-SCR-000015 | B24: OC-SCR-001457 | C24: 00 | D24: REH-MD01-MDU-TE-OC-Hil-1046-SCR-000015 - Clarification of Apartment Type Discrepancy - PLOT 1046-FIRST FLOOR | E24: 1046 | F24: 46302 | H24: Pending
A25: REH-MD01-MDU-TE-OC-Hil-1046-SCR-000016 | B25: OC-SCR-001475 | C25: 00 | D25: REH-MD01-MDU-TE-OC-Hil-1046-SCR-000016 - Clarification of Camera Data Outlets - PLOT 1046-FIRST FLOOR | E25: 1046 | F25: 46302 | H25: Pending
